Workbook

Sheet 配当金単価推移
A1: コード | B1: 銘柄名 | C1: 配当金分配年月
C2: 配当金単価（税引き後）
C3: 【特定】保有数 / 受取金額（税引き後）
C4: 【NISA】保有数 / 受取金額（税引き後）
A5: HDV | B5: iシェアーズ コア 米国高配当株 ETF | C5: 45352 | E5: 45444 | G5: 45566 | I5: 45627 | K5: 45717 | M5: 45809 | O5: 45901 | Q5: 45992
C6: =IFERROR(__xludf.DUMMYFUNCTION("FILTER('配当金履歴一覧'!$D:$D,('配当金履歴一覧'!$C:$C=C5)*('配当金履歴一覧'!$B:$B=$B5))"),"0.75USD") -> 0.75USD | E6: =IFERROR(__xludf.DUMMYFUNCTION("FILTER('配当金履歴一覧'!$D:$D,('配当金履歴一覧'!$C:$C=E5)*('配当金履歴一覧'!$B:$B=$B5))"),"0.83USD") -> 0.83USD | G6: =IFERROR(__xludf.DUMMYFUNCTION("FILTER('配当金履歴一覧'!$D:$D,('配当金履歴一覧'!$C:$C=G5)*('配当金履歴一覧'!$B:$B=$B5))"),"1.1USD") -> 1.1USD | I6: =IFERROR(__xludf.DUMMYFUNCTION("FILTER('配当金履歴一覧'!$D:$D,('配当金履歴一覧'!$C:$C=I5)*('配当金履歴一覧'!$B:$B=$B5))"),"1.01USD") -> 1.01USD | K6: =IFERROR(__xludf.DUMMYFUNCTION("FILTER('配当金履歴一覧'!$D:$D,('配当金履歴一覧'!$C:$C=K5)*('配当金履歴一覧'!$B:$B=$B5))"),"0.71USD") -> 0.71USD | M6: =IFERROR(__xludf.DUMMYFUNCTION("FILTER('配当金履歴一覧'!$D:$D,('配当金履歴一覧'!$C:$C=M5)*('配当金履歴一覧'!$B:$B=$B5))"),"0.82USD") -> 0.82USD | O6: =IFERROR(__xludf.DUMMYFUNCTION("FILTER('配当金履歴一覧'!$D:$D,('配当金履歴一覧'!$C:$C=O5)*('配当金履歴一覧'!$B:$B=$B5))"),"0.85USD") -> 0.85USD | Q6: =IFERROR(__xludf.DUMMYFUNCTION("FILTER('配当金履歴一覧'!$D:$D,('配当金履歴一覧'!$C:$C=Q5)*('配当金履歴一覧'!$B:$B=$B5))"),"1.12USD") -> 1.12USD
C7: =IFERROR(__xludf.DUMMYFUNCTION("FILTER('配当金履歴一覧'!$E:$E,('配当金履歴一覧'!$C:$C=C5)*('配当金履歴一覧'!$B:$B=$B5))"),51.0) -> 51 | D7: =IFERROR(__xludf.DUMMYFUNCTION("FILTER('配当金履歴一覧'!$F:$F,('配当金履歴一覧'!$C:$C=C5)*('配当金履歴一覧'!$B:$B=$B5))"),4605.0) -> 4605 | E7: =IFERROR(__xludf.DUMMYFUNCTION("FILTER('配当金履歴一覧'!$E:$E,('配当金履歴一覧'!$C:$C=E5)*('配当金履歴一覧'!$B:$B=$B5))"),51.0) -> 51 | F7: =IFERROR(__xludf.DUMMYFUNCTION("FILTER('配当金履歴一覧'!$F:$F,('配当金履歴一覧'!$C:$C=E5)*('配当金履歴一覧'!$B:$B=$B5))"),5316.0) -> 5316 | G7: =IFERROR(__xludf.DUMMYFUNCTION("FILTER('配当金履歴一覧'!$E:$E,('配当金履歴一覧'!$C:$C=G5)*('配当金履歴一覧'!$B:$B=$B5))"),51.0) -> 51 | H7: =IFERROR(__xludf.DUMMYFUNCTION("FILTER('配当金履歴一覧'!$F:$F,('配当金履歴一覧'!$C:$C=G5)*('配当金履歴一覧'!$B:$B=$B5))"),6381.0) -> 6381 | I7: =IFERROR(__xludf.DUMMYFUNCTION("FILTER('配当金履歴一覧'!$E:$E,('配当金履歴一覧'!$C:$C=I5)*('配当金履歴一覧'!$B:$B=$B5))"),51.0) -> 51 | J7: =IFERROR(__xludf.DUMMYFUNCTION("FILTER('配当金履歴一覧'!$F:$F,('配当金履歴一覧'!$C:$C=I5)*('配当金履歴一覧'!$B:$B=$B5))"),6442.0) -> 6442 | K7: =IFERROR(__xludf.DUMMYFUNCTION("FILTER('配当金履歴一覧'!$E:$E,('配当金履歴一覧'!$C:$C=K5)*('配当金履歴一覧'!$B:$B=$B5))"),51.0) -> 51 | L7: =IFERROR(__xludf.DUMMYFUNCTION("FILTER('配当金履歴一覧'!$F:$F,('配当金履歴一覧'!$C:$C=K5)*('配当金履歴一覧'!$B:$B=$B5))"),4311.0) -> 4311 | M7: =IFERROR(__xludf.DUMMYFUNCTION("FILTER('配当金履歴一覧'!$E:$E,('配当金履歴一覧'!$C:$C=M5)*('配当金履歴一覧'!$B:$B=$B5))"),51.0) -> 51 | N7: =IFERROR(__xludf.DUMMYFUNCTION("FILTER('配当金履歴一覧'!$F:$F,('配当金履歴一覧'!$C:$C=M5)*('配当金履歴一覧'!$B:$B=$B5))"),4821.0) -> 4821 | O7: =IFERROR(__xludf.DUMMYFUNCTION("FILTER('配当金履歴一覧'!$E:$E,('配当金履歴一覧'!$C:$C=O5)*('配当金履歴一覧'!$B:$B=$B5))"),51.0) -> 51 | P7: =IFERROR(__xludf.DUMMYFUNCTION("FILTER('配当金履歴一覧'!$F:$F,('配当金履歴一覧'!$C:$C=O5)*('配当金履歴一覧'!$B:$B=$B5))"),5111.0) -> 5111 | Q7: =IFERROR(__xludf.DUMMYFUNCTION("FILTER('配当金履歴一覧'!$E:$E,('配当金履歴一覧'!$C:$C=Q5)*('配当金履歴一覧'!$B:$B=$B5))"),51.0) -> 51 | R7: =IFERROR(__xludf.DUMMYFUNCTION("FILTER('配当金履歴一覧'!$F:$F,('配当金履歴一覧'!$C:$C=Q5)*('配当金履歴一覧'!$B:$B=$B5))"),7097.0) -> 7097
C8: =IFERROR(__xludf.DUMMYFUNCTION("FILTER('配当金履歴一覧'!$G:$G,('配当金履歴一覧'!$C:$C=C5)*('配当金履歴一覧'!$B:$B=$B5))"),3.0) -> 3 | D8: =IFERROR(__xludf.DUMMYFUNCTION("FILTER('配当金履歴一覧'!$H:$H,('配当金履歴一覧'!$C:$C=C5)*('配当金履歴一覧'!$B:$B=$B5))"),113.3) -> 113.3 | E8: =IFERROR(__xludf.DUMMYFUNCTION("FILTER('配当金履歴一覧'!$G:$G,('配当金履歴一覧'!$C:$C=E5)*('配当金履歴一覧'!$B:$B=$B5))"),6.0) -> 6 | F8: =IFERROR(__xludf.DUMMYFUNCTION("FILTER('配当金履歴一覧'!$H:$H,('配当金履歴一覧'!$C:$C=E5)*('配当金履歴一覧'!$B:$B=$B5))"),785.0) -> 785 | G8: =IFERROR(__xludf.DUMMYFUNCTION("FILTER('配当金履歴一覧'!$G:$G,('配当金履歴一覧'!$C:$C=G5)*('配当金履歴一覧'!$B:$B=$B5))"),6.0) -> 6 | H8: =IFERROR(__xludf.DUMMYFUNCTION("FILTER('配当金履歴一覧'!$H:$H,('配当金履歴一覧'!$C:$C=G5)*('配当金履歴一覧'!$B:$B=$B5))"),942.0) -> 942 | I8: =IFERROR(__xludf.DUMMYFUNCTION("FILTER('配当金履歴一覧'!$G:$G,('配当金履歴一覧'!$C:$C=I5)*('配当金履歴一覧'!$B:$B=$B5))"),8.0) -> 8 | J8: =IFERROR(__xludf.DUMMYFUNCTION("FILTER('配当金履歴一覧'!$H:$H,('配当金履歴一覧'!$C:$C=I5)*('配当金履歴一覧'!$B:$B=$B5))"),1268.0) -> 1268 | K8: =IFERROR(__xludf.DUMMYFUNCTION("FILTER('配当金履歴一覧'!$G:$G,('配当金履歴一覧'!$C:$C=K5)*('配当金履歴一覧'!$B:$B=$B5))"),13.0) -> 13 | L8: =IFERROR(__xludf.DUMMYFUNCTION("FILTER('配当金履歴一覧'!$H:$H,('配当金履歴一覧'!$C:$C=K5)*('配当金履歴一覧'!$B:$B=$B5))"),1379.0) -> 1379 | M8: =IFERROR(__xludf.DUMMYFUNCTION("FILTER('配当金履歴一覧'!$G:$G,('配当金履歴一覧'!$C:$C=M5)*('配当金履歴一覧'!$B:$B=$B5))"),16.0) -> 16 | N8: =IFERROR(__xludf.DUMMYFUNCTION("FILTER('配当金履歴一覧'!$H:$H,('配当金履歴一覧'!$C:$C=M5)*('配当金履歴一覧'!$B:$B=$B5))"),1898.0) -> 1898 | O8: =IFERROR(__xludf.DUMMYFUNCTION("FILTER('配当金履歴一覧'!$G:$G,('配当金履歴一覧'!$C:$C=O5)*('配当金履歴一覧'!$B:$B=$B5))"),17.0) -> 17 | P8: =IFERROR(__xludf.DUMMYFUNCTION("FILTER('配当金履歴一覧'!$H:$H,('配当金履歴一覧'!$C:$C=O5)*('配当金履歴一覧'!$B:$B=$B5))"),2138.0) -> 2138 | Q8: =IFERROR(__xludf.DUMMYFUNCTION("FILTER('配当金履歴一覧'!$G:$G,('配当金履歴一覧'!$C:$C=Q5)*('配当金履歴一覧'!$B:$B=$B5))"),18.0) -> 18 | R8: =IFERROR(__xludf.DUMMYFUNCTION("FILTER('配当金履歴一覧'!$H:$H,('配当金履歴一覧'!$C:$C=Q5)*('配当金履歴一覧'!$B:$B=$B5))"),3143.0) -> 3143
A9: VYM | B9: バンガード 米国高配当株式ETF | C9: 45352 | E9: 45444 | G9: 45536 | I9: 45627 | K9: 45717 | M9: 45809 | O9: 45901 | Q9: 45992
C10: =IFERROR(__xludf.DUMMYFUNCTION("FILTER('配当金履歴一覧'!$D:$D,('配当金履歴一覧'!$C:$C=C9)*('配当金履歴一覧'!$B:$B=$B9))"),"0.59USD") -> 0.59USD | E10: =IFERROR(__xludf.DUMMYFUNCTION("FILTER('配当金履歴一覧'!$D:$D,('配当金履歴一覧'!$C:$C=E9)*('配当金履歴一覧'!$B:$B=$B9))"),"0.92USD") -> 0.92USD | G10: =IFERROR(__xludf.DUMMYFUNCTION("FILTER('配当金履歴一覧'!$D:$D,('配当金履歴一覧'!$C:$C=G9)*('配当金履歴一覧'!$B:$B=$B9))"),"0.76USD") -> 0.76USD | I10: =IFERROR(__xludf.DUMMYFUNCTION("FILTER('配当金履歴一覧'!$D:$D,('配当金履歴一覧'!$C:$C=I9)*('配当金履歴一覧'!$B:$B=$B9))"),"0.86USD") -> 0.86USD | K10: =IFERROR(__xludf.DUMMYFUNCTION("FILTER('配当金履歴一覧'!$D:$D,('配当金履歴一覧'!$C:$C=K9)*('配当金履歴一覧'!$B:$B=$B9))"),"0.76USD") -> 0.76USD | M10: =IFERROR(__xludf.DUMMYFUNCTION("FILTER('配当金履歴一覧'!$D:$D,('配当金履歴一覧'!$C:$C=M9)*('配当金履歴一覧'!$B:$B=$B9))"),"0.77USD") -> 0.77USD | O10: =IFERROR(__xludf.DUMMYFUNCTION("FILTER('配当金履歴一覧'!$D:$D,('配当金履歴一覧'!$C:$C=O9)*('配当金履歴一覧'!$B:$B=$B9))"),"0.75USD") -> 0.75USD | Q10: =IFERROR(__xludf.DUMMYFUNCTION("FILTER('配当金履歴一覧'!$D:$D,('配当金履歴一覧'!$C:$C=Q9)*('配当金履歴一覧'!$B:$B=$B9))"),"0.85USD") -> 0.85USD
C11: =IFERROR(__xludf.DUMMYFUNCTION("FILTER('配当金履歴一覧'!$G:$G,('配当金履歴一覧'!$C:$C=C9)*('配当金履歴一覧'!$B:$B=$B9))"),2.0) -> 2 | D11: =IFERROR(__xludf.DUMMYFUNCTION("FILTER('配当金履歴一覧'!$H:$H,('配当金履歴一覧'!$C:$C=C9)*('配当金履歴一覧'!$B:$B=$B9))"),174.0) -> 174 | E11: =IFERROR(__xludf.DUMMYFUNCTION("FILTER('配当金履歴一覧'!$G:$G,('配当金履歴一覧'!$C:$C=E9)*('配当金履歴一覧'!$B:$B=$B9))"),8.0) -> 8 | F11: =IFERROR(__xludf.DUMMYFUNCTION("FILTER('配当金履歴一覧'!$H:$H,('配当金履歴一覧'!$C:$C=E9)*('配当金履歴一覧'!$B:$B=$B9))"),1170.0) -> 1170 | G11: =IFERROR(__xludf.DUMMYFUNCTION("FILTER('配当金履歴一覧'!$G:$G,('配当金履歴一覧'!$C:$C=G9)*('配当金履歴一覧'!$B:$B=$B9))"),8.0) -> 8 | H11: =IFERROR(__xludf.DUMMYFUNCTION("FILTER('配当金履歴一覧'!$H:$H,('配当金履歴一覧'!$C:$C=G9)*('配当金履歴一覧'!$B:$B=$B9))"),874.0) -> 874 | I11: =IFERROR(__xludf.DUMMYFUNCTION("FILTER('配当金履歴一覧'!$G:$G,('配当金履歴一覧'!$C:$C=I9)*('配当金履歴一覧'!$B:$B=$B9))"),9.0) -> 9 | J11: =IFERROR(__xludf.DUMMYFUNCTION("FILTER('配当金履歴一覧'!$H:$H,('配当金履歴一覧'!$C:$C=I9)*('配当金履歴一覧'!$B:$B=$B9))"),1223.0) -> 1223 | K11: =IFERROR(__xludf.DUMMYFUNCTION("FILTER('配当金履歴一覧'!$G:$G,('配当金履歴一覧'!$C:$C=K9)*('配当金履歴一覧'!$B:$B=$B9))"),12.0) -> 12 | L11: =IFERROR(__xludf.DUMMYFUNCTION("FILTER('配当金履歴一覧'!$H:$H,('配当金履歴一覧'!$C:$C=K9)*('配当金履歴一覧'!$B:$B=$B9))"),1378.0) -> 1378 | M11: =IFERROR(__xludf.DUMMYFUNCTION("FILTER('配当金履歴一覧'!$G:$G,('配当金履歴一覧'!$C:$C=M9)*('配当金履歴一覧'!$B:$B=$B9))"),17.0) -> 17 | N11: =IFERROR(__xludf.DUMMYFUNCTION("FILTER('配当金履歴一覧'!$H:$H,('配当金履歴一覧'!$C:$C=M9)*('配当金履歴一覧'!$B:$B=$B9))"),1908.0) -> 1908 | O11: =IFERROR(__xludf.DUMMYFUNCTION("FILTER('配当金履歴一覧'!$G:$G,('配当金履歴一覧'!$C:$C=O9)*('配当金履歴一覧'!$B:$B=$B9))"),18.0) -> 18 | P11: =IFERROR(__xludf.DUMMYFUNCTION("FILTER('配当金履歴一覧'!$H:$H,('配当金履歴一覧'!$C:$C=O9)*('配当金履歴一覧'!$B:$B=$B9))"),2010.0) -> 2010 | Q11: =IFERROR(__xludf.DUMMYFUNCTION("FILTER('配当金履歴一覧'!$G:$G,('配当金履歴一覧'!$C:$C=Q9)*('配当金履歴一覧'!$B:$B=$B9))"),19.0) -> 19 | R11: =IFERROR(__xludf.DUMMYFUNCTION("FILTER('配当金履歴一覧'!$H:$H,('配当金履歴一覧'!$C:$C=Q9)*('配当金履歴一覧'!$B:$B=$B9))"),2524.0) -> 2524
A12: SPYD | B12: SPDRポートフォリオS&P 500高配当株式ETF | C12: 45352 | E12: 45444 | G12: 45536 | I12: 45627 | K12: 45717 | M12: 45809 | O12: 45901 | Q12: 45992
C13: =IFERROR(__xludf.DUMMYFUNCTION("FILTER('配当金履歴一覧'!$D:$D,('配当金履歴一覧'!$C:$C=C12)*('配当金履歴一覧'!$B:$B=$B12))"),"0.33USD") -> 0.33USD | E13: =IFERROR(__xludf.DUMMYFUNCTION("FILTER('配当金履歴一覧'!$D:$D,('配当金履歴一覧'!$C:$C=E12)*('配当金履歴一覧'!$B:$B=$B12))"),"0.43USD") -> 0.43USD | G13: =IFERROR(__xludf.DUMMYFUNCTION("FILTER('配当金履歴一覧'!$D:$D,('配当金履歴一覧'!$C:$C=G12)*('配当金履歴一覧'!$B:$B=$B12))"),"0.41USD") -> 0.41USD | I13: =IFERROR(__xludf.DUMMYFUNCTION("FILTER('配当金履歴一覧'!$D:$D,('配当金履歴一覧'!$C:$C=I12)*('配当金履歴一覧'!$B:$B=$B12))"),"0.49USD") -> 0.49USD | K13: =IFERROR(__xludf.DUMMYFUNCTION("FILTER('配当金履歴一覧'!$D:$D,('配当金履歴一覧'!$C:$C=K12)*('配当金履歴一覧'!$B:$B=$B12))"),"0.37USD") -> 0.37USD | M13: =IFERROR(__xludf.DUMMYFUNCTION("FILTER('配当金履歴一覧'!$D:$D,('配当金履歴一覧'!$C:$C=M12)*('配当金履歴一覧'!$B:$B=$B12))"),"0.45USD") -> 0.45USD | O13: =IFERROR(__xludf.DUMMYFUNCTION("FILTER('配当金履歴一覧'!$D:$D,('配当金履歴一覧'!$C:$C=O12)*('配当金履歴一覧'!$B:$B=$B12))"),"0.44USD") -> 0.44USD | Q13: =IFERROR(__xludf.DUMMYFUNCTION("FILTER('配当金履歴一覧'!$D:$D,('配当金履歴一覧'!$C:$C=Q12)*('配当金履歴一覧'!$B:$B=$B12))"),"0.49USD") -> 0.49USD
C14: =IFERROR(__xludf.DUMMYFUNCTION("FILTER('配当金履歴一覧'!$E:$E,('配当金履歴一覧'!$C:$C=C12)*('配当金履歴一覧'!$B:$B=$B12))"),191.0) -> 191 | D14: =IFERROR(__xludf.DUMMYFUNCTION("FILTER('配当金履歴一覧'!$F:$F,('配当金履歴一覧'!$C:$C=C12)*('配当金履歴一覧'!$B:$B=$B12))"),7580.0) -> 7580 | E14: =IFERROR(__xludf.DUMMYFUNCTION("FILTER('配当金履歴一覧'!$E:$E,('配当金履歴一覧'!$C:$C=E12)*('配当金履歴一覧'!$B:$B=$B12))"),191.0) -> 191 | F14: =IFERROR(__xludf.DUMMYFUNCTION("FILTER('配当金履歴一覧'!$F:$F,('配当金履歴一覧'!$C:$C=E12)*('配当金履歴一覧'!$B:$B=$B12))"),10578.0) -> 10578 | G14: =IFERROR(__xludf.DUMMYFUNCTION("FILTER('配当金履歴一覧'!$E:$E,('配当金履歴一覧'!$C:$C=G12)*('配当金履歴一覧'!$B:$B=$B12))"),191.0) -> 191 | H14: =IFERROR(__xludf.DUMMYFUNCTION("FILTER('配当金履歴一覧'!$F:$F,('配当金履歴一覧'!$C:$C=G12)*('配当金履歴一覧'!$B:$B=$B12))"),8928.0) -> 8928 | I14: =IFERROR(__xludf.DUMMYFUNCTION("FILTER('配当金履歴一覧'!$E:$E,('配当金履歴一覧'!$C:$C=I12)*('配当金履歴一覧'!$B:$B=$B12))"),191.0) -> 191 | J14: =IFERROR(__xludf.DUMMYFUNCTION("FILTER('配当金履歴一覧'!$F:$F,('配当金履歴一覧'!$C:$C=I12)*('配当金履歴一覧'!$B:$B=$B12))"),11720.0) -> 11720 | K14: =IFERROR(__xludf.DUMMYFUNCTION("FILTER('配当金履歴一覧'!$E:$E,('配当金履歴一覧'!$C:$C=K12)*('配当金履歴一覧'!$B:$B=$B12))"),191.0) -> 191 | L14: =IFERROR(__xludf.DUMMYFUNCTION("FILTER('配当金履歴一覧'!$F:$F,('配当金履歴一覧'!$C:$C=K12)*('配当金履歴一覧'!$B:$B=$B12))"),8562.0) -> 8562 | M14: =IFERROR(__xludf.DUMMYFUNCTION("FILTER('配当金履歴一覧'!$E:$E,('配当金履歴一覧'!$C:$C=M12)*('配当金履歴一覧'!$B:$B=$B12))"),191.0) -> 191 | N14: =IFERROR(__xludf.DUMMYFUNCTION("FILTER('配当金履歴一覧'!$F:$F,('配当金履歴一覧'!$C:$C=M12)*('配当金履歴一覧'!$B:$B=$B12))"),9858.0) -> 9858 | O14: =IFERROR(__xludf.DUMMYFUNCTION("FILTER('配当金履歴一覧'!$E:$E,('配当金履歴一覧'!$C:$C=O12)*('配当金履歴一覧'!$B:$B=$B12))"),191.0) -> 191 | P14: =IFERROR(__xludf.DUMMYFUNCTION("FILTER('配当金履歴一覧'!$F:$F,('配当金履歴一覧'!$C:$C=O12)*('配当金履歴一覧'!$B:$B=$B12))"),9842.0) -> 9842 | Q14: =IFERROR(__xludf.DUMMYFUNCTION("FILTER('配当金履歴一覧'!$E:$E,('配当金履歴一覧'!$C:$C=Q12)*('配当金履歴一覧'!$B:$B=$B12))"),191.0) -> 191 | R14: =IFERROR(__xludf.DUMMYFUNCTION("FILTER('配当金履歴一覧'!$F:$F,('配当金履歴一覧'!$C:$C=Q12)*('配当金履歴一覧'!$B:$B=$B12))"),11689.0) -> 11689
C15: =IFERROR(__xludf.DUMMYFUNCTION("FILTER('配当金履歴一覧'!$G:$G,('配当金履歴一覧'!$C:$C=C12)*('配当金履歴一覧'!$B:$B=$B12))"),5.0) -> 5 | D15: =IFERROR(__xludf.DUMMYFUNCTION("FILTER('配当金履歴一覧'!$H:$H,('配当金履歴一覧'!$C:$C=C12)*('配当金履歴一覧'!$B:$B=$B12))"),249.0) -> 249 | E15: =IFERROR(__xludf.DUMMYFUNCTION("FILTER('配当金履歴一覧'!$G:$G,('配当金履歴一覧'!$C:$C=E12)*('配当金履歴一覧'!$B:$B=$B12))"),6.0) -> 6 | F15: =IFERROR(__xludf.DUMMYFUNCTION("FILTER('配当金履歴一覧'!$H:$H,('配当金履歴一覧'!$C:$C=E12)*('配当金履歴一覧'!$B:$B=$B12))"),417.0) -> 417 | G15: =IFERROR(__xludf.DUMMYFUNCTION("FILTER('配当金履歴一覧'!$G:$G,('配当金履歴一覧'!$C:$C=G12)*('配当金履歴一覧'!$B:$B=$B12))"),6.0) -> 6 | H15: =IFERROR(__xludf.DUMMYFUNCTION("FILTER('配当金履歴一覧'!$H:$H,('配当金履歴一覧'!$C:$C=G12)*('配当金履歴一覧'!$B:$B=$B12))"),352.0) -> 352 | I15: =IFERROR(__xludf.DUMMYFUNCTION("FILTER('配当金履歴一覧'!$G:$G,('配当金履歴一覧'!$C:$C=I12)*('配当金履歴一覧'!$B:$B=$B12))"),8.0) -> 8 | J15: =IFERROR(__xludf.DUMMYFUNCTION("FILTER('配当金履歴一覧'!$H:$H,('配当金履歴一覧'!$C:$C=I12)*('配当金履歴一覧'!$B:$B=$B12))"),616.0) -> 616 | K15: =IFERROR(__xludf.DUMMYFUNCTION("FILTER('配当金履歴一覧'!$G:$G,('配当金履歴一覧'!$C:$C=K12)*('配当金履歴一覧'!$B:$B=$B12))"),8.0) -> 8 | L15: =IFERROR(__xludf.DUMMYFUNCTION("FILTER('配当金履歴一覧'!$H:$H,('配当金履歴一覧'!$C:$C=K12)*('配当金履歴一覧'!$B:$B=$B12))"),450.0) -> 450 | M15: =IFERROR(__xludf.DUMMYFUNCTION("FILTER('配当金履歴一覧'!$G:$G,('配当金履歴一覧'!$C:$C=M12)*('配当金履歴一覧'!$B:$B=$B12))"),9.0) -> 9 | N15: =IFERROR(__xludf.DUMMYFUNCTION("FILTER('配当金履歴一覧'!$H:$H,('配当金履歴一覧'!$C:$C=M12)*('配当金履歴一覧'!$B:$B=$B12))"),583.0) -> 583 | O15: =IFERROR(__xludf.DUMMYFUNCTION("FILTER('配当金履歴一覧'!$G:$G,('配当金履歴一覧'!$C:$C=O12)*('配当金履歴一覧'!$B:$B=$B12))"),9.0) -> 9 | P15: =IFERROR(__xludf.DUMMYFUNCTION("FILTER('配当金履歴一覧'!$H:$H,('配当金履歴一覧'!$C:$C=O12)*('配当金履歴一覧'!$B:$B=$B12))"),582.0) -> 582 | Q15: =IFERROR(__xludf.DUMMYFUNCTION("FILTER('配当金履歴一覧'!$G:$G,('配当金履歴一覧'!$C:$C=Q12)*('配当金履歴一覧'!$B:$B=$B12))"),10.0) -> 10 | R15: =IFERROR(__xludf.DUMMYFUNCTION("FILTER('配当金履歴一覧'!$H:$H,('配当金履歴一覧'!$C:$C=Q12)*('配当金履歴一覧'!$B:$B=$B12))"),768.0) -> 768
A16: 1605 | B16: INPEX | C16: 45536 | E16: 45717 | G16: 45901
C17: =IFERROR(__xludf.DUMMYFUNCTION("FILTER('配当金履歴一覧'!$D:$D,('配当金履歴一覧'!$C:$C=C16)*('配当金履歴一覧'!$B:$B=$B16))"),43.0) -> 43 | E17: =IFERROR(__xludf.DUMMYFUNCTION("FILTER('配当金履歴一覧'!$D:$D,('配当金履歴一覧'!$C:$C=E16)*('配当金履歴一覧'!$B:$B=$B16))"),43.0) -> 43 | G17: =IFERROR(__xludf.DUMMYFUNCTION("FILTER('配当金履歴一覧'!$D:$D,('配当金履歴一覧'!$C:$C=G16)*('配当金履歴一覧'!$B:$B=$B16))"),50.0) -> 50
C18: =IFERROR(__xludf.DUMMYFUNCTION("FILTER('配当金履歴一覧'!$G:$G,('配当金履歴一覧'!$C:$C=C16)*('配当金履歴一覧'!$B:$B=$B16))"),4.0) -> 4 | D18: =IFERROR(__xludf.DUMMYFUNCTION("FILTER('配当金履歴一覧'!$H:$H,('配当金履歴一覧'!$C:$C=C16)*('配当金履歴一覧'!$B:$B=$B16))"),172.0) -> 172 | E18: =IFERROR(__xludf.DUMMYFUNCTION("FILTER('配当金履歴一覧'!$G:$G,('配当金履歴一覧'!$C:$C=E16)*('配当金履歴一覧'!$B:$B=$B16))"),13.0) -> 13 | F18: =IFERROR(__xludf.DUMMYFUNCTION("FILTER('配当金履歴一覧'!$H:$H,('配当金履歴一覧'!$C:$C=E16)*('配当金履歴一覧'!$B:$B=$B16))"),559.0) -> 559 | G18: =IFERROR(__xludf.DUMMYFUNCTION("FILTER('配当金履歴一覧'!$G:$G,('配当金履歴一覧'!$C:$C=G16)*('配当金履歴一覧'!$B:$B=$B16))"),26.0) -> 26 | H18: =IFERROR(__xludf.DUMMYFUNCTION("FILTER('配当金履歴一覧'!$H:$H,('配当金履歴一覧'!$C:$C=G16)*('配当金履歴一覧'!$B:$B=$B16))"),1300.0) -> 1300
A19: 1808 | B19: 長谷工コーポレーション | C19: 45444 | E19: 45627 | G19: 45809 | I19: 45992
C20: =IFERROR(__xludf.DUMMYFUNCTION("FILTER('配当金履歴一覧'!$D:$D,('配当金履歴一覧'!$C:$C=C19)*('配当金履歴一覧'!$B:$B=$B19))"),45.0) -> 45 | E20: =IFERROR(__xludf.DUMMYFUNCTION("FILTER('配当金履歴一覧'!$D:$D,('配当金履歴一覧'!$C:$C=E19)*('配当金履歴一覧'!$B:$B=$B19))"),40.0) -> 40 | G20: =IFERROR(__xludf.DUMMYFUNCTION("FILTER('配当金履歴一覧'!$D:$D,('配当金履歴一覧'!$C:$C=G19)*('配当金履歴一覧'!$B:$B=$B19))"),45.0) -> 45 | I20: =IFERROR(__xludf.DUMMYFUNCTION("FILTER('配当金履歴一覧'!$D:$D,('配当金履歴一覧'!$C:$C=I19)*('配当金履歴一覧'!$B:$B=$B19))"),45.0) -> 45
C21: =IFERROR(__xludf.DUMMYFUNCTION("FILTER('配当金履歴一覧'!$E:$E,('配当金履歴一覧'!$C:$C=C19)*('配当金履歴一覧'!$B:$B=$B19))"),8.0) -> 8 | D21: =IFERROR(__xludf.DUMMYFUNCTION("FILTER('配当金履歴一覧'!$F:$F,('配当金履歴一覧'!$C:$C=C19)*('配当金履歴一覧'!$B:$B=$B19))"),287.0) -> 287 | E21: =IFERROR(__xludf.DUMMYFUNCTION("FILTER('配当金履歴一覧'!$E:$E,('配当金履歴一覧'!$C:$C=E19)*('配当金履歴一覧'!$B:$B=$B19))"),8.0) -> 8 | F21: =IFERROR(__xludf.DUMMYFUNCTION("FILTER('配当金履歴一覧'!$F:$F,('配当金履歴一覧'!$C:$C=E19)*('配当金履歴一覧'!$B:$B=$B19))"),255.0) -> 255 | G21: =IFERROR(__xludf.DUMMYFUNCTION("FILTER('配当金履歴一覧'!$E:$E,('配当金履歴一覧'!$C:$C=G19)*('配当金履歴一覧'!$B:$B=$B19))"),8.0) -> 8 | H21: =IFERROR(__xludf.DUMMYFUNCTION("FILTER('配当金履歴一覧'!$F:$F,('配当金履歴一覧'!$C:$C=G19)*('配当金履歴一覧'!$B:$B=$B19))"),287.0) -> 287 | I21: =IFERROR(__xludf.DUMMYFUNCTION("FILTER('配当金履歴一覧'!$E:$E,('配当金履歴一覧'!$C:$C=I19)*('配当金履歴一覧'!$B:$B=$B19))"),8.0) -> 8 | J21: =IFERROR(__xludf.DUMMYFUNCTION("FILTER('配当金履歴一覧'!$F:$F,('配当金履歴一覧'!$C:$C=I19)*('配当金履歴一覧'!$B:$B=$B19))"),287.0) -> 287
C22: =IFERROR(__xludf.DUMMYFUNCTION("FILTER('配当金履歴一覧'!$G:$G,('配当金履歴一覧'!$C:$C=C19)*('配当金履歴一覧'!$B:$B=$B19))"),0.0) -> 0 | D22: =IFERROR(__xludf.DUMMYFUNCTION("FILTER('配当金履歴一覧'!$H:$H,('配当金履歴一覧'!$C:$C=C19)*('配当金履歴一覧'!$B:$B=$B19))"),0.0) -> 0 | E22: =IFERROR(__xludf.DUMMYFUNCTION("FILTER('配当金履歴一覧'!$G:$G,('配当金履歴一覧'!$C:$C=E19)*('配当金履歴一覧'!$B:$B=$B19))"),4.0) -> 4 | F22: =IFERROR(__xludf.DUMMYFUNCTION("FILTER('配当金履歴一覧'!$H:$H,('配当金履歴一覧'!$C:$C=E19)*('配当金履歴一覧'!$B:$B=$B19))"),160.0) -> 160 | G22: =IFERROR(__xludf.DUMMYFUNCTION("FILTER('配当金履歴一覧'!$G:$G,('配当金履歴一覧'!$C:$C=G19)*('配当金履歴一覧'!$B:$B=$B19))"),6.0) -> 6 | H22: =IFERROR(__xludf.DUMMYFUNCTION("FILTER('配当金履歴一覧'!$H:$H,('配当金履歴一覧'!$C:$C=G19)*('配当金履歴一覧'!$B:$B=$B19))"),270.0) -> 270 | I22: =IFERROR(__xludf.DUMMYFUNCTION("FILTER('配当金履歴一覧'!$G:$G,('配当金履歴一覧'!$C:$C=I19)*('配当金履歴一覧'!$B:$B=$B19))"),6.0) -> 6 | J22: =IFERROR(__xludf.DUMMYFUNCTION("FILTER('配当金履歴一覧'!$H:$H,('配当金履歴一覧'!$C:$C=I19)*('配当金履歴一覧'!$B:$B=$B19))"),270.0) -> 270
A23: 1911 | B23: 住友林業 | C23: 45352 | E23: 45536 | G23: 45717 | I23: 45901
C24: =IFERROR(__xludf.DUMMYFUNCTION("FILTER('配当金履歴一覧'!$D:$D,('配当金履歴一覧'!$C:$C=C23)*('配当金履歴一覧'!$B:$B=$B23))"),65.0) -> 65 | E24: =IFERROR(__xludf.DUMMYFUNCTION("FILTER('配当金履歴一覧'!$D:$D,('配当金履歴一覧'!$C:$C=E23)*('配当金履歴一覧'!$B:$B=$B23))"),65.0) -> 65 | G24: =IFERROR(__xludf.DUMMYFUNCTION("FILTER('配当金履歴一覧'!$D:$D,('配当金履歴一覧'!$C:$C=G23)*('配当金履歴一覧'!$B:$B=$B23))"),80.0) -> 80 | I24: =IFERROR(__xludf.DUMMYFUNCTION("FILTER('配当金履歴一覧'!$D:$D,('配当金履歴一覧'!$C:$C=I23)*('配当金履歴一覧'!$B:$B=$B23))"),75.0) -> 75
C25: =IFERROR(__xludf.DUMMYFUNCTION("FILTER('配当金履歴一覧'!$E:$E,('配当金履歴一覧'!$C:$C=C23)*('配当金履歴一覧'!$B:$B=$B23))"),16.0) -> 16 | D25: =IFERROR(__xludf.DUMMYFUNCTION("FILTER('配当金履歴一覧'!$F:$F,('配当金履歴一覧'!$C:$C=C23)*('配当金履歴一覧'!$B:$B=$B23))"),829.0) -> 829 | E25: =IFERROR(__xludf.DUMMYFUNCTION("FILTER('配当金履歴一覧'!$E:$E,('配当金履歴一覧'!$C:$C=E23)*('配当金履歴一覧'!$B:$B=$B23))"),16.0) -> 16 | F25: =IFERROR(__xludf.DUMMYFUNCTION("FILTER('配当金履歴一覧'!$F:$F,('配当金履歴一覧'!$C:$C=E23)*('配当金履歴一覧'!$B:$B=$B23))"),829.0) -> 829 | G25: =IFERROR(__xludf.DUMMYFUNCTION("FILTER('配当金履歴一覧'!$E:$E,('配当金履歴一覧'!$C:$C=G23)*('配当金履歴一覧'!$B:$B=$B23))"),16.0) -> 16 | H25: =IFERROR(__xludf.DUMMYFUNCTION("FILTER('配当金履歴一覧'!$F:$F,('配当金履歴一覧'!$C:$C=G23)*('配当金履歴一覧'!$B:$B=$B23))"),1020.0) -> 1020 | I25: =IFERROR(__xludf.DUMMYFUNCTION("FILTER('配当金履歴一覧'!$E:$E,('配当金履歴一覧'!$C:$C=I23)*('配当金履歴一覧'!$B:$B=$B23))"),16.0) -> 16 | J25: =IFERROR(__xludf.DUMMYFUNCTION("FILTER('配当金履歴一覧'!$F:$F,('配当金履歴一覧'!$C:$C=I23)*('配当金履歴一覧'!$B:$B=$B23))"),957.0) -> 957
C26: =IFERROR(__xludf.DUMMYFUNCTION("FILTER('配当金履歴一覧'!$G:$G,('配当金履歴一覧'!$C:$C=C23)*('配当金履歴一覧'!$B:$B=$B23))"),0.0) -> 0 | D26: =IFERROR(__xludf.DUMMYFUNCTION("FILTER('配当金履歴一覧'!$H:$H,('配当金履歴一覧'!$C:$C=C23)*('配当金履歴一覧'!$B:$B=$B23))"),0.0) -> 0 | E26: =IFERROR(__xludf.DUMMYFUNCTION("FILTER('配当金履歴一覧'!$G:$G,('配当金履歴一覧'!$C:$C=E23)*('配当金履歴一覧'!$B:$B=$B23))"),5.0) -> 5 | F26: =IFERROR(__xludf.DUMMYFUNCTION("FILTER('配当金履歴一覧'!$H:$H,('配当金履歴一覧'!$C:$C=E23)*('配当金履歴一覧'!$B:$B=$B23))"),325.0) -> 325 | G26: =IFERROR(__xludf.DUMMYFUNCTION("FILTER('配当金履歴一覧'!$G:$G,('配当金履歴一覧'!$C:$C=G23)*('配当金履歴一覧'!$B:$B=$B23))"),6.0) -> 6 | H26: =IFERROR(__xludf.DUMMYFUNCTION("FILTER('配当金履歴一覧'!$H:$H,('配当金履歴一覧'!$C:$C=G23)*('配当金履歴一覧'!$B:$B=$B23))"),480.0) -> 480 | I26: =IFERROR(__xludf.DUMMYFUNCTION("FILTER('配当金履歴一覧'!$G:$G,('配当金履歴一覧'!$C:$C=I23)*('配当金履歴一覧'!$B:$B=$B23))"),9.0) -> 9 | J26: =IFERROR(__xludf.DUMMYFUNCTION("FILTER('配当金履歴一覧'!$H:$H,('配当金履歴一覧'!$C:$C=I23)*('配当金履歴一覧'!$B:$B=$B23))"),675.0) -> 675
A27: 1925 | B27: 大和ハウス工業 | C27: 45444 | E27: 45627 | G27: 45809 | I27: 45992
C28: =IFERROR(__xludf.DUMMYFUNCTION("FILTER('配当金履歴一覧'!$D:$D,('配当金履歴一覧'!$C:$C=C27)*('配当金履歴一覧'!$B:$B=$B27))"),80.0) -> 80 | E28: =IFERROR(__xludf.DUMMYFUNCTION("FILTER('配当金履歴一覧'!$D:$D,('配当金履歴一覧'!$C:$C=E27)*('配当金履歴一覧'!$B:$B=$B27))"),70.0) -> 70 | G28: =IFERROR(__xludf.DUMMYFUNCTION("FILTER('配当金履歴一覧'!$D:$D,('配当金履歴一覧'!$C:$C=G27)*('配当金履歴一覧'!$B:$B=$B27))"),80.0) -> 80 | I28: =IFERROR(__xludf.DUMMYFUNCTION("FILTER('配当金履歴一覧'!$D:$D,('配当金履歴一覧'!$C:$C=I27)*('配当金履歴一覧'!$B:$B=$B27))"),75.0) -> 75
C29: =IFERROR(__xludf.DUMMYFUNCTION("FILTER('配当金履歴一覧'!$E:$E,('配当金履歴一覧'!$C:$C=C27)*('配当金履歴一覧'!$B:$B=$B27))"),8.0) -> 8 | D29: =IFERROR(__xludf.DUMMYFUNCTION("FILTER('配当金履歴一覧'!$F:$F,('配当金履歴一覧'!$C:$C=C27)*('配当金履歴一覧'!$B:$B=$B27))"),510.0) -> 510 | E29: =IFERROR(__xludf.DUMMYFUNCTION("FILTER('配当金履歴一覧'!$E:$E,('配当金履歴一覧'!$C:$C=E27)*('配当金履歴一覧'!$B:$B=$B27))"),8.0) -> 8 | F29: =IFERROR(__xludf.DUMMYFUNCTION("FILTER('配当金履歴一覧'!$F:$F,('配当金履歴一覧'!$C:$C=E27)*('配当金履歴一覧'!$B:$B=$B27))"),447.0) -> 447 | G29: =IFERROR(__xludf.DUMMYFUNCTION("FILTER('配当金履歴一覧'!$E:$E,('配当金履歴一覧'!$C:$C=G27)*('配当金履歴一覧'!$B:$B=$B27))"),8.0) -> 8 | H29: =IFERROR(__xludf.DUMMYFUNCTION("FILTER('配当金履歴一覧'!$F:$F,('配当金履歴一覧'!$C:$C=G27)*('配当金履歴一覧'!$B:$B=$B27))"),510.0) -> 510 | I29: =IFERROR(__xludf.DUMMYFUNCTION("FILTER('配当金履歴一覧'!$E:$E,('配当金履歴一覧'!$C:$C=I27)*('配当金履歴一覧'!$B:$B=$B27))"),8.0) -> 8 | J29: =IFERROR(__xludf.DUMMYFUNCTION("FILTER('配当金履歴一覧'!$F:$F,('配当金履歴一覧'!$C:$C=I27)*('配当金履歴一覧'!$B:$B=$B27))"),479.0) -> 479
C30: =IFERROR(__xludf.DUMMYFUNCTION("FILTER('配当金履歴一覧'!$G:$G,('配当金履歴一覧'!$C:$C=C27)*('配当金履歴一覧'!$B:$B=$B27))"),1.0) -> 1 | D30: =IFERROR(__xludf.DUMMYFUNCTION("FILTER('配当金履歴一覧'!$H:$H,('配当金履歴一覧'!$C:$C=C27)*('配当金履歴一覧'!$B:$B=$B27))"),80.0) -> 80 | E30: =IFERROR(__xludf.DUMMYFUNCTION("FILTER('配当金履歴一覧'!$G:$G,('配当金履歴一覧'!$C:$C=E27)*('配当金履歴一覧'!$B:$B=$B27))"),5.0) -> 5 | F30: =IFERROR(__xludf.DUMMYFUNCTION("FILTER('配当金履歴一覧'!$H:$H,('配当金履歴一覧'!$C:$C=E27)*('配当金履歴一覧'!$B:$B=$B27))"),350.0) -> 350 | G30: =IFERROR(__xludf.DUMMYFUNCTION("FILTER('配当金履歴一覧'!$G:$G,('配当金履歴一覧'!$C:$C=G27)*('配当金履歴一覧'!$B:$B=$B27))"),5.0) -> 5 | H30: =IFERROR(__xludf.DUMMYFUNCTION("FILTER('配当金履歴一覧'!$H:$H,('配当金履歴一覧'!$C:$C=G27)*('配当金履歴一覧'!$B:$B=$B27))"),400.0) -> 400 | I30: =IFERROR(__xludf.DUMMYFUNCTION("FILTER('配当金履歴一覧'!$G:$G,('配当金履歴一覧'!$C:$C=I27)*('配当金履歴一覧'!$B:$B=$B27))"),5.0) -> 5 | J30: =IFERROR(__xludf.DUMMYFUNCTION("FILTER('配当金履歴一覧'!$H:$H,('配当金履歴一覧'!$C:$C=I27)*('配当金履歴一覧'!$B:$B=$B27))"),375.0) -> 375
A31: 1928 | B31: 積水ハウス | C31: 45383 | E31: 45536 | G31: 45748 | I31: 45901
C32: =IFERROR(__xludf.DUMMYFUNCTION("FILTER('配当金履歴一覧'!$D:$D,('配当金履歴一覧'!$C:$C=C31)*('配当金履歴一覧'!$B:$B=$B31))"),64.0) -> 64 | E32: =IFERROR(__xludf.DUMMYFUNCTION("FILTER('配当金履歴一覧'!$D:$D,('配当金履歴一覧'!$C:$C=E31)*('配当金履歴一覧'!$B:$B=$B31))"),64.0) -> 64 | G32: =IFERROR(__xludf.DUMMYFUNCTION("FILTER('配当金履歴一覧'!$D:$D,('配当金履歴一覧'!$C:$C=G31)*('配当金履歴一覧'!$B:$B=$B31))"),71.0) -> 71 | I32: =IFERROR(__xludf.DUMMYFUNCTION("FILTER('配当金履歴一覧'!$D:$D,('配当金履歴一覧'!$C:$C=I31)*('配当金履歴一覧'!$B:$B=$B31))"),72.0) -> 72
C33: =IFERROR(__xludf.DUMMYFUNCTION("FILTER('配当金履歴一覧'!$E:$E,('配当金履歴一覧'!$C:$C=C31)*('配当金履歴一覧'!$B:$B=$B31))"),15.0) -> 15 | D33: =IFERROR(__xludf.DUMMYFUNCTION("FILTER('配当金履歴一覧'!$F:$F,('配当金履歴一覧'!$C:$C=C31)*('配当金履歴一覧'!$B:$B=$B31))"),765.0) -> 765 | E33: =IFERROR(__xludf.DUMMYFUNCTION("FILTER('配当金履歴一覧'!$E:$E,('配当金履歴一覧'!$C:$C=E31)*('配当金履歴一覧'!$B:$B=$B31))"),15.0) -> 15 | F33: =IFERROR(__xludf.DUMMYFUNCTION("FILTER('配当金履歴一覧'!$F:$F,('配当金履歴一覧'!$C:$C=E31)*('配当金履歴一覧'!$B:$B=$B31))"),765.0) -> 765 | G33: =IFERROR(__xludf.DUMMYFUNCTION("FILTER('配当金履歴一覧'!$E:$E,('配当金履歴一覧'!$C:$C=G31)*('配当金履歴一覧'!$B:$B=$B31))"),15.0) -> 15 | H33: =IFERROR(__xludf.DUMMYFUNCTION("FILTER('配当金履歴一覧'!$F:$F,('配当金履歴一覧'!$C:$C=G31)*('配当金履歴一覧'!$B:$B=$B31))"),849.0) -> 849 | I33: =IFERROR(__xludf.DUMMYFUNCTION("FILTER('配当金履歴一覧'!$E:$E,('配当金履歴一覧'!$C:$C=I31)*('配当金履歴一覧'!$B:$B=$B31))"),15.0) -> 15 | J33: =IFERROR(__xludf.DUMMYFUNCTION("FILTER('配当金履歴一覧'!$F:$F,('配当金履歴一覧'!$C:$C=I31)*('配当金履歴一覧'!$B:$B=$B31))"),861.0) -> 861
C34: =IFERROR(__xludf.DUMMYFUNCTION("FILTER('配当金履歴一覧'!$G:$G,('配当金履歴一覧'!$C:$C=C31)*('配当金履歴一覧'!$B:$B=$B31))"),0.0) -> 0 | D34: =IFERROR(__xludf.DUMMYFUNCTION("FILTER('配当金履歴一覧'!$H:$H,('配当金履歴一覧'!$C:$C=C31)*('配当金履歴一覧'!$B:$B=$B31))"),0.0) -> 0 | E34: =IFERROR(__xludf.DUMMYFUNCTION("FILTER('配当金履歴一覧'!$G:$G,('配当金履歴一覧'!$C:$C=E31)*('配当金履歴一覧'!$B:$B=$B31))"),2.0) -> 2 | F34: =IFERROR(__xludf.DUMMYFUNCTION("FILTER('配当金履歴一覧'!$H:$H,('配当金履歴一覧'!$C:$C=E31)*('配当金履歴一覧'!$B:$B=$B31))"),128.0) -> 128 | G34: =IFERROR(__xludf.DUMMYFUNCTION("FILTER('配当金履歴一覧'!$G:$G,('配当金履歴一覧'!$C:$C=G31)*('配当金履歴一覧'!$B:$B=$B31))"),4.0) -> 4 | H34: =IFERROR(__xludf.DUMMYFUNCTION("FILTER('配当金履歴一覧'!$H:$H,('配当金履歴一覧'!$C:$C=G31)*('配当金履歴一覧'!$B:$B=$B31))"),284.0) -> 284 | I34: =IFERROR(__xludf.DUMMYFUNCTION("FILTER('配当金履歴一覧'!$G:$G,('配当金履歴一覧'!$C:$C=I31)*('配当金履歴一覧'!$B:$B=$B31))"),9.0) -> 9 | J34: =IFERROR(__xludf.DUMMYFUNCTION("FILTER('配当金履歴一覧'!$H:$H,('配当金履歴一覧'!$C:$C=I31)*('配当金履歴一覧'!$B:$B=$B31))"),648.0) -> 648
A35: 2124 | B35: ジェイエイシーリクルートメント | C35: 45352 | E35: 45717
C36: =IFERROR(__xludf.DUMMYFUNCTION("FILTER('配当金履歴一覧'!$D:$D,('配当金履歴一覧'!$C:$C=C35)*('配当金履歴一覧'!$B:$B=$B35))"),90.0) -> 90 | E36: =IFERROR(__xludf.DUMMYFUNCTION("FILTER('配当金履歴一覧'!$D:$D,('配当金履歴一覧'!$C:$C=E35)*('配当金履歴一覧'!$B:$B=$B35))"),26.0) -> 26
C37: =IFERROR(__xludf.DUMMYFUNCTION("FILTER('配当金履歴一覧'!$E:$E,('配当金履歴一覧'!$C:$C=C35)*('配当金履歴一覧'!$B:$B=$B35))"),16.0) -> 16 | D37: =IFERROR(__xludf.DUMMYFUNCTION("FILTER('配当金履歴一覧'!$F:$F,('配当金履歴一覧'!$C:$C=C35)*('配当金履歴一覧'!$B:$B=$B35))"),1148.0) -> 1148 | E37: =IFERROR(__xludf.DUMMYFUNCTION("FILTER('配当金履歴一覧'!$E:$E,('配当金履歴一覧'!$C:$C=E35)*('配当金履歴一覧'!$B:$B=$B35))"),64.0) -> 64 | F37: =IFERROR(__xludf.DUMMYFUNCTION("FILTER('配当金履歴一覧'!$F:$F,('配当金履歴一覧'!$C:$C=E35)*('配当金履歴一覧'!$B:$B=$B35))"),1327.0) -> 1327
C38: =IFERROR(__xludf.DUMMYFUNCTION("FILTER('配当金履歴一覧'!$G:$G,('配当金履歴一覧'!$C:$C=C35)*('配当金履歴一覧'!$B:$B=$B35))"),0.0) -> 0 | D38: =IFERROR(__xludf.DUMMYFUNCTION("FILTER('配当金履歴一覧'!$H:$H,('配当金履歴一覧'!$C:$C=C35)*('配当金履歴一覧'!$B:$B=$B35))"),0.0) -> 0 | E38: =IFERROR(__xludf.DUMMYFUNCTION("FILTER('配当金履歴一覧'!$G:$G,('配当金履歴一覧'!$C:$C=E35)*('配当金履歴一覧'!$B:$B=$B35))"),10.0) -> 10 | F38: =IFERROR(__xludf.DUMMYFUNCTION("FILTER('配当金履歴一覧'!$H:$H,('配当金履歴一覧'!$C:$C=E35)*('配当金履歴一覧'!$B:$B=$B35))"),260.0) -> 260
A39: 2503 | B39: キリンホールディングス | C39: 45352 | E39: 45536 | G39: 45717 | I39: 45901
C40: =IFERROR(__xludf.DUMMYFUNCTION("FILTER('配当金履歴一覧'!$D:$D,('配当金履歴一覧'!$C:$C=C39)*('配当金履歴一覧'!$B:$B=$B39))"),36.5) -> 36.5 | E40: =IFERROR(__xludf.DUMMYFUNCTION("FILTER('配当金履歴一覧'!$D:$D,('配当金履歴一覧'!$C:$C=E39)*('配当金履歴一覧'!$B:$B=$B39))"),35.5) -> 35.5 | G40: =IFERROR(__xludf.DUMMYFUNCTION("FILTER('配当金履歴一覧'!$D:$D,('配当金履歴一覧'!$C:$C=G39)*('配当金履歴一覧'!$B:$B=$B39))"),35.5) -> 35.5 | I40: =IFERROR(__xludf.DUMMYFUNCTION("FILTER('配当金履歴一覧'!$D:$D,('配当金履歴一覧'!$C:$C=I39)*('配当金履歴一覧'!$B:$B=$B39))"),37.0) -> 37
...

Sheet 年間配当金総額
A1: 2024年間配当金総額 | C1: 45292 | D1: 45323 | E1: 45352 | F1: 45383 | G1: 45413 | H1: 45444 | I1: 45474 | J1: 45505 | K1: 45536 | L1: 45566 | M1: 45597 | N1: 45627
A2: =SUM(B2:N2) -> 110785.3 | C2: =SUMIF('配当金履歴一覧'!$C:$C,C1,'配当金履歴一覧'!$F:$F)+SUMIF('配当金履歴一覧'!$C:$C,C1,'配当金履歴一覧'!$H:$H) -> 0 | D2: =SUMIF('配当金履歴一覧'!$C:$C,D1,'配当金履歴一覧'!$F:$F)+SUMIF('配当金履歴一覧'!$C:$C,D1,'配当金履歴一覧'!$H:$H) -> 0 | E2: =SUMIF('配当金履歴一覧'!$C:$C,E1,'配当金履歴一覧'!$F:$F)+SUMIF('配当金履歴一覧'!$C:$C,E1,'配当金履歴一覧'!$H:$H) -> 15187.3 | F2: =SUMIF('配当金履歴一覧'!$C:$C,F1,'配当金履歴一覧'!$F:$F)+SUMIF('配当金履歴一覧'!$C:$C,F1,'配当金履歴一覧'!$H:$H) -> 765 | G2: =SUMIF('配当金履歴一覧'!$C:$C,G1,'配当金履歴一覧'!$F:$F)+SUMIF('配当金履歴一覧'!$C:$C,G1,'配当金履歴一覧'!$H:$H) -> 0 | H2: =SUMIF('配当金履歴一覧'!$C:$C,H1,'配当金履歴一覧'!$F:$F)+SUMIF('配当金履歴一覧'!$C:$C,H1,'配当金履歴一覧'!$H:$H) -> 33569 | I2: =SUMIF('配当金履歴一覧'!$C:$C,I1,'配当金履歴一覧'!$F:$F)+SUMIF('配当金履歴一覧'!$C:$C,I1,'配当金履歴一覧'!$H:$H) -> 0 | J2: =SUMIF('配当金履歴一覧'!$C:$C,J1,'配当金履歴一覧'!$F:$F)+SUMIF('配当金履歴一覧'!$C:$C,J1,'配当金履歴一覧'!$H:$H) -> 346 | ... N2: =SUMIF('配当金履歴一覧'!$C:$C,N1,'配当金履歴一覧'!$F:$F)+SUMIF('配当金履歴一覧'!$C:$C,N1,'配当金履歴一覧'!$H:$H) -> 38962
A4: 2025年間配当金総額 | C4: 45658 | D4: 45689 | E4: 45717 | F4: 45748 | G4: 45778 | H4: 45809 | I4: 45839 | J4: 45870 | K4: 45901 | L4: 45931 | M4: 45962 | N4: 45992
A5: =SUM(B5:N5) -> 148195 | C5: =SUMIF('配当金履歴一覧'!$C:$C,C4,'配当金履歴一覧'!$F:$F)+SUMIF('配当金履歴一覧'!$C:$C,C4,'配当金履歴一覧'!$H:$H) -> 0 | D5: =SUMIF('配当金履歴一覧'!$C:$C,D4,'配当金履歴一覧'!$F:$F)+SUMIF('配当金履歴一覧'!$C:$C,D4,'配当金履歴一覧'!$H:$H) -> 0 | E5: =SUMIF('配当金履歴一覧'!$C:$C,E4,'配当金履歴一覧'!$F:$F)+SUMIF('配当金履歴一覧'!$C:$C,E4,'配当金履歴一覧'!$H:$H) -> 21710 | F5: =SUMIF('配当金履歴一覧'!$C:$C,F4,'配当金履歴一覧'!$F:$F)+SUMIF('配当金履歴一覧'!$C:$C,F4,'配当金履歴一覧'!$H:$H) -> 1133 | G5: =SUMIF('配当金履歴一覧'!$C:$C,G4,'配当金履歴一覧'!$F:$F)+SUMIF('配当金履歴一覧'!$C:$C,G4,'配当金履歴一覧'!$H:$H) -> 0 | H5: =SUMIF('配当金履歴一覧'!$C:$C,H4,'配当金履歴一覧'!$F:$F)+SUMIF('配当金履歴一覧'!$C:$C,H4,'配当金履歴一覧'!$H:$H) -> 42431 | I5: =SUMIF('配当金履歴一覧'!$C:$C,I4,'配当金履歴一覧'!$F:$F)+SUMIF('配当金履歴一覧'!$C:$C,I4,'配当金履歴一覧'!$H:$H) -> 1731 | J5: =SUMIF('配当金履歴一覧'!$C:$C,J4,'配当金履歴一覧'!$F:$F)+SUMIF('配当金履歴一覧'!$C:$C,J4,'配当金履歴一覧'!$H:$H) -> 528 | ... N5: =SUMIF('配当金履歴一覧'!$C:$C,N4,'配当金履歴一覧'!$F:$F)+SUMIF('配当金履歴一覧'!$C:$C,N4,'配当金履歴一覧'!$H:$H) -> 52154
A7: 2026年間配当金総額 | C7: 46023 | D7: 46054 | E7: 46082 | F7: 46113 | G7: 46143 | H7: 46174 | I7: 46204 | J7: 46235 | K7: 46266 | L7: 46296 | M7: 46327 | N7: 46357
A8: =SUM(B8:N8) -> 0 | C8: =SUMIF('配当金履歴一覧'!$C:$C,C7,'配当金履歴一覧'!$F:$F)+SUMIF('配当金履歴一覧'!$C:$C,C7,'配当金履歴一覧'!$H:$H) -> 0 | D8: =SUMIF('配当金履歴一覧'!$C:$C,D7,'配当金履歴一覧'!$F:$F)+SUMIF('配当金履歴一覧'!$C:$C,D7,'配当金履歴一覧'!$H:$H) -> 0 | E8: =SUMIF('配当金履歴一覧'!$C:$C,E7,'配当金履歴一覧'!$F:$F)+SUMIF('配当金履歴一覧'!$C:$C,E7,'配当金履歴一覧'!$H:$H) -> 0 | F8: =SUMIF('配当金履歴一覧'!$C:$C,F7,'配当金履歴一覧'!$F:$F)+SUMIF('配当金履歴一覧'!$C:$C,F7,'配当金履歴一覧'!$H:$H) -> 0 | G8: =SUMIF('配当金履歴一覧'!$C:$C,G7,'配当金履歴一覧'!$F:$F)+SUMIF('配当金履歴一覧'!$C:$C,G7,'配当金履歴一覧'!$H:$H) -> 0 | H8: =SUMIF('配当金履歴一覧'!$C:$C,H7,'配当金履歴一覧'!$F:$F)+SUMIF('配当金履歴一覧'!$C:$C,H7,'配当金履歴一覧'!$H:$H) -> 0 | I8: =SUMIF('配当金履歴一覧'!$C:$C,I7,'配当金履歴一覧'!$F:$F)+SUMIF('配当金履歴一覧'!$C:$C,I7,'配当金履歴一覧'!$H:$H) -> 0 | J8: =SUMIF('配当金履歴一覧'!$C:$C,J7,'配当金履歴一覧'!$F:$F)+SUMIF('配当金履歴一覧'!$C:$C,J7,'配当金履歴一覧'!$H:$H) -> 0 | ... N8: =SUMIF('配当金履歴一覧'!$C:$C,N7,'配当金履歴一覧'!$F:$F)+SUMIF('配当金履歴一覧'!$C:$C,N7,'配当金履歴一覧'!$H:$H) -> 0
A10: コード | B10: 銘柄名 | C10: 銘柄別年間配当金総額
C11: 2024年 | D11: 2025年 | E11: 2026年
A12: 米国株 | C12: =SUM(C14:C16) -> 69733.3 | D12: =SUM(D14:D16) -> 80052 | E12: =SUM(E14:E16) -> 0
A14: HDV | B14: iシェアーズ コア 米国高配当株 ETF | C14: =SUMIFS('配当金履歴一覧'!$F:F,'配当金履歴一覧'!$C:$C,">=2024/1",'配当金履歴一覧'!$C:$C,"<=2024/12",'配当金履歴一覧'!$B:$B,$B14)+SUMIFS('配当金履歴一覧'!$H:H,'配当金履歴一覧'!$C:$C,">=2024/1",'配当金履歴一覧'!$C:$C,"<=2024/12",'配当金履歴一覧'!$B:$B,$B14) -> 25852.3 | D14: =SUMIFS('配当金履歴一覧'!$F:F,'配当金履歴一覧'!$C:$C,">=2025/1",'配当金履歴一覧'!$C:$C,"<=2025/12",'配当金履歴一覧'!$B:$B,$B14)+SUMIFS('配当金履歴一覧'!$H:H,'配当金履歴一覧'!$C:$C,">=2025/1",'配当金履歴一覧'!$C:$C,"<=2025/12",'配当金履歴一覧'!$B:$B,$B14) -> 29898 | E14: =SUMIFS('配当金履歴一覧'!$F:F,'配当金履歴一覧'!$C:$C,">=2026/1",'配当金履歴一覧'!$C:$C,"<=2026/12",'配当金履歴一覧'!$B:$B,$B14)+SUMIFS('配当金履歴一覧'!$H:H,'配当金履歴一覧'!$C:$C,">=2026/1",'配当金履歴一覧'!$C:$C,"<=2026/12",'配当金履歴一覧'!$B:$B,$B14) -> 0
A15: VYM | B15: バンガード 米国高配当株式ETF | C15: =SUMIFS('配当金履歴一覧'!$F:F,'配当金履歴一覧'!$C:$C,">=2024/1",'配当金履歴一覧'!$C:$C,"<=2024/12",'配当金履歴一覧'!$B:$B,$B15)+SUMIFS('配当金履歴一覧'!$H:H,'配当金履歴一覧'!$C:$C,">=2024/1",'配当金履歴一覧'!$C:$C,"<=2024/12",'配当金履歴一覧'!$B:$B,$B15) -> 3441 | D15: =SUMIFS('配当金履歴一覧'!$F:F,'配当金履歴一覧'!$C:$C,">=2025/1",'配当金履歴一覧'!$C:$C,"<=2025/12",'配当金履歴一覧'!$B:$B,$B15)+SUMIFS('配当金履歴一覧'!$H:H,'配当金履歴一覧'!$C:$C,">=2025/1",'配当金履歴一覧'!$C:$C,"<=2025/12",'配当金履歴一覧'!$B:$B,$B15) -> 7820 | E15: =SUMIFS('配当金履歴一覧'!$F:F,'配当金履歴一覧'!$C:$C,">=2026/1",'配当金履歴一覧'!$C:$C,"<=2026/12",'配当金履歴一覧'!$B:$B,$B15)+SUMIFS('配当金履歴一覧'!$H:H,'配当金履歴一覧'!$C:$C,">=2026/1",'配当金履歴一覧'!$C:$C,"<=2026/12",'配当金履歴一覧'!$B:$B,$B15) -> 0
A16: SPYD | B16: SPDRポートフォリオS&P 500高配当株式ETF | C16: =SUMIFS('配当金履歴一覧'!$F:F,'配当金履歴一覧'!$C:$C,">=2024/1",'配当金履歴一覧'!$C:$C,"<=2024/12",'配当金履歴一覧'!$B:$B,$B16)+SUMIFS('配当金履歴一覧'!$H:H,'配当金履歴一覧'!$C:$C,">=2024/1",'配当金履歴一覧'!$C:$C,"<=2024/12",'配当金履歴一覧'!$B:$B,$B16) -> 40440 | D16: =SUMIFS('配当金履歴一覧'!$F:F,'配当金履歴一覧'!$C:$C,">=2025/1",'配当金履歴一覧'!$C:$C,"<=2025/12",'配当金履歴一覧'!$B:$B,$B16)+SUMIFS('配当金履歴一覧'!$H:H,'配当金履歴一覧'!$C:$C,">=2025/1",'配当金履歴一覧'!$C:$C,"<=2025/12",'配当金履歴一覧'!$B:$B,$B16) -> 42334 | E16: =SUMIFS('配当金履歴一覧'!$F:F,'配当金履歴一覧'!$C:$C,">=2026/1",'配当金履歴一覧'!$C:$C,"<=2026/12",'配当金履歴一覧'!$B:$B,$B16)+SUMIFS('配当金履歴一覧'!$H:H,'配当金履歴一覧'!$C:$C,">=2026/1",'配当金履歴一覧'!$C:$C,"<=2026/12",'配当金履歴一覧'!$B:$B,$B16) -> 0
A17: 日本株 | C17: =SUM(C19:C56) -> 41052 | D17: =SUM(D19:D56) -> 68143 | E17: =SUM(E19:E56) -> 0
A19: 1605 | B19: INPEX | C19: =SUMIFS('配当金履歴一覧'!$F:F,'配当金履歴一覧'!$C:$C,">=2024/1",'配当金履歴一覧'!$C:$C,"<=2024/12",'配当金履歴一覧'!$B:$B,$B19)+SUMIFS('配当金履歴一覧'!$H:H,'配当金履歴一覧'!$C:$C,">=2024/1",'配当金履歴一覧'!$C:$C,"<=2024/12",'配当金履歴一覧'!$B:$B,$B19) -> 172 | D19: =SUMIFS('配当金履歴一覧'!$F:F,'配当金履歴一覧'!$C:$C,">=2025/1",'配当金履歴一覧'!$C:$C,"<=2025/12",'配当金履歴一覧'!$B:$B,$B19)+SUMIFS('配当金履歴一覧'!$H:H,'配当金履歴一覧'!$C:$C,">=2025/1",'配当金履歴一覧'!$C:$C,"<=2025/12",'配当金履歴一覧'!$B:$B,$B19) -> 1859 | E19: =SUMIFS('配当金履歴一覧'!$F:F,'配当金履歴一覧'!$C:$C,">=2026/1",'配当金履歴一覧'!$C:$C,"<=2026/12",'配当金履歴一覧'!$B:$B,$B19)+SUMIFS('配当金履歴一覧'!$H:H,'配当金履歴一覧'!$C:$C,">=2026/1",'配当金履歴一覧'!$C:$C,"<=2026/12",'配当金履歴一覧'!$B:$B,$B19) -> 0
A20: 1801 | B20: 長谷工コーポレーション | C20: =SUMIFS('配当金履歴一覧'!$F:F,'配当金履歴一覧'!$C:$C,">=2024/1",'配当金履歴一覧'!$C:$C,"<=2024/12",'配当金履歴一覧'!$B:$B,$B20)+SUMIFS('配当金履歴一覧'!$H:H,'配当金履歴一覧'!$C:$C,">=2024/1",'配当金履歴一覧'!$C:$C,"<=2024/12",'配当金履歴一覧'!$B:$B,$B20) -> 702 | D20: =SUMIFS('配当金履歴一覧'!$F:F,'配当金履歴一覧'!$C:$C,">=2025/1",'配当金履歴一覧'!$C:$C,"<=2025/12",'配当金履歴一覧'!$B:$B,$B20)+SUMIFS('配当金履歴一覧'!$H:H,'配当金履歴一覧'!$C:$C,">=2025/1",'配当金履歴一覧'!$C:$C,"<=2025/12",'配当金履歴一覧'!$B:$B,$B20) -> 1114 | E20: =SUMIFS('配当金履歴一覧'!$F:F,'配当金履歴一覧'!$C:$C,">=2026/1",'配当金履歴一覧'!$C:$C,"<=2026/12",'配当金履歴一覧'!$B:$B,$B20)+SUMIFS('配当金履歴一覧'!$H:H,'配当金履歴一覧'!$C:$C,">=2026/1",'配当金履歴一覧'!$C:$C,"<=2026/12",'配当金履歴一覧'!$B:$B,$B20) -> 0
A21: 1911 | B21: 住友林業 | C21: =SUMIFS('配当金履歴一覧'!$F:F,'配当金履歴一覧'!$C:$C,">=2024/1",'配当金履歴一覧'!$C:$C,"<=2024/12",'配当金履歴一覧'!$B:$B,$B21)+SUMIFS('配当金履歴一覧'!$H:H,'配当金履歴一覧'!$C:$C,">=2024/1",'配当金履歴一覧'!$C:$C,"<=2024/12",'配当金履歴一覧'!$B:$B,$B21) -> 1983 | D21: =SUMIFS('配当金履歴一覧'!$F:F,'配当金履歴一覧'!$C:$C,">=2025/1",'配当金履歴一覧'!$C:$C,"<=2025/12",'配当金履歴一覧'!$B:$B,$B21)+SUMIFS('配当金履歴一覧'!$H:H,'配当金履歴一覧'!$C:$C,">=2025/1",'配当金履歴一覧'!$C:$C,"<=2025/12",'配当金履歴一覧'!$B:$B,$B21) -> 3132 | E21: =SUMIFS('配当金履歴一覧'!$F:F,'配当金履歴一覧'!$C:$C,">=2026/1",'配当金履歴一覧'!$C:$C,"<=2026/12",'配当金履歴一覧'!$B:$B,$B21)+SUMIFS('配当金履歴一覧'!$H:H,'配当金履歴一覧'!$C:$C,">=2026/1",'配当金履歴一覧'!$C:$C,"<=2026/12",'配当金履歴一覧'!$B:$B,$B21) -> 0
A22: 1925 | B22: 大和ハウス工業 | C22: =SUMIFS('配当金履歴一覧'!$F:F,'配当金履歴一覧'!$C:$C,">=2024/1",'配当金履歴一覧'!$C:$C,"<=2024/12",'配当金履歴一覧'!$B:$B,$B22)+SUMIFS('配当金履歴一覧'!$H:H,'配当金履歴一覧'!$C:$C,">=2024/1",'配当金履歴一覧'!$C:$C,"<=2024/12",'配当金履歴一覧'!$B:$B,$B22) -> 1387 | D22: =SUMIFS('配当金履歴一覧'!$F:F,'配当金履歴一覧'!$C:$C,">=2025/1",'配当金履歴一覧'!$C:$C,"<=2025/12",'配当金履歴一覧'!$B:$B,$B22)+SUMIFS('配当金履歴一覧'!$H:H,'配当金履歴一覧'!$C:$C,">=2025/1",'配当金履歴一覧'!$C:$C,"<=2025/12",'配当金履歴一覧'!$B:$B,$B22) -> 1764 | E22: =SUMIFS('配当金履歴一覧'!$F:F,'配当金履歴一覧'!$C:$C,">=2026/1",'配当金履歴一覧'!$C:$C,"<=2026/12",'配当金履歴一覧'!$B:$B,$B22)+SUMIFS('配当金履歴一覧'!$H:H,'配当金履歴一覧'!$C:$C,">=2026/1",'配当金履歴一覧'!$C:$C,"<=2026/12",'配当金履歴一覧'!$B:$B,$B22) -> 0
A23: 1928 | B23: 積水ハウス | C23: =SUMIFS('配当金履歴一覧'!$F:F,'配当金履歴一覧'!$C:$C,">=2024/1",'配当金履歴一覧'!$C:$C,"<=2024/12",'配当金履歴一覧'!$B:$B,$B23)+SUMIFS('配当金履歴一覧'!$H:H,'配当金履歴一覧'!$C:$C,">=2024/1",'配当金履歴一覧'!$C:$C,"<=2024/12",'配当金履歴一覧'!$B:$B,$B23) -> 1658 | D23: =SUMIFS('配当金履歴一覧'!$F:F,'配当金履歴一覧'!$C:$C,">=2025/1",'配当金履歴一覧'!$C:$C,"<=2025/12",'配当金履歴一覧'!$B:$B,$B23)+SUMIFS('配当金履歴一覧'!$H:H,'配当金履歴一覧'!$C:$C,">=2025/1",'配当金履歴一覧'!$C:$C,"<=2025/12",'配当金履歴一覧'!$B:$B,$B23) -> 2642 | E23: =SUMIFS('配当金履歴一覧'!$F:F,'配当金履歴一覧'!$C:$C,">=2026/1",'配当金履歴一覧'!$C:$C,"<=2026/12",'配当金履歴一覧'!$B:$B,$B23)+SUMIFS('配当金履歴一覧'!$H:H,'配当金履歴一覧'!$C:$C,">=2026/1",'配当金履歴一覧'!$C:$C,"<=2026/12",'配当金履歴一覧'!$B:$B,$B23) -> 0
A24: 2124 | B24: ジェイエイシーリクルートメント | C24: =SUMIFS('配当金履歴一覧'!$F:F,'配当金履歴一覧'!$C:$C,">=2024/1",'配当金履歴一覧'!$C:$C,"<=2024/12",'配当金履歴一覧'!$B:$B,$B24)+SUMIFS('配当金履歴一覧'!$H:H,'配当金履歴一覧'!$C:$C,">=2024/1",'配当金履歴一覧'!$C:$C,"<=2024/12",'配当金履歴一覧'!$B:$B,$B24) -> 1148 | D24: =SUMIFS('配当金履歴一覧'!$F:F,'配当金履歴一覧'!$C:$C,">=2025/1",'配当金履歴一覧'!$C:$C,"<=2025/12",'配当金履歴一覧'!$B:$B,$B24)+SUMIFS('配当金履歴一覧'!$H:H,'配当金履歴一覧'!$C:$C,">=2025/1",'配当金履歴一覧'!$C:$C,"<=2025/12",'配当金履歴一覧'!$B:$B,$B24) -> 1587 | E24: =SUMIFS('配当金履歴一覧'!$F:F,'配当金履歴一覧'!$C:$C,">=2026/1",'配当金履歴一覧'!$C:$C,"<=2026/12",'配当金履歴一覧'!$B:$B,$B24)+SUMIFS('配当金履歴一覧'!$H:H,'配当金履歴一覧'!$C:$C,">=2026/1",'配当金履歴一覧'!$C:$C,"<=2026/12",'配当金履歴一覧'!$B:$B,$B24) -> 0
A25: 2503 | B25: キリンホールディングス | C25: =SUMIFS('配当金履歴一覧'!$F:F,'配当金履歴一覧'!$C:$C,">=2024/1",'配当金履歴一覧'!$C:$C,"<=2024/12",'配当金履歴一覧'!$B:$B,$B25)+SUMIFS('配当金履歴一覧'!$H:H,'配当金履歴一覧'!$C:$C,">=2024/1",'配当金履歴一覧'!$C:$C,"<=2024/12",'配当金履歴一覧'!$B:$B,$B25) -> 590 | D25: =SUMIFS('配当金履歴一覧'!$F:F,'配当金履歴一覧'!$C:$C,">=2025/1",'配当金履歴一覧'!$C:$C,"<=2025/12",'配当金履歴一覧'!$B:$B,$B25)+SUMIFS('配当金履歴一覧'!$H:H,'配当金履歴一覧'!$C:$C,">=2025/1",'配当金履歴一覧'!$C:$C,"<=2025/12",'配当金履歴一覧'!$B:$B,$B25) -> 743 | E25: =SUMIFS('配当金履歴一覧'!$F:F,'配当金履歴一覧'!$C:$C,">=2026/1",'配当金履歴一覧'!$C:$C,"<=2026/12",'配当金履歴一覧'!$B:$B,$B25)+SUMIFS('配当金履歴一覧'!$H:H,'配当金履歴一覧'!$C:$C,">=2026/1",'配当金履歴一覧'!$C:$C,"<=2026/12",'配当金履歴一覧'!$B:$B,$B25) -> 0
A26: 2768 | B26: 双日 | C26: =SUMIFS('配当金履歴一覧'!$F:F,'配当金履歴一覧'!$C:$C,">=2024/1",'配当金履歴一覧'!$C:$C,"<=2024/12",'配当金履歴一覧'!$B:$B,$B26)+SUMIFS('配当金履歴一覧'!$H:H,'配当金履歴一覧'!$C:$C,">=2024/1",'配当金履歴一覧'!$C:$C,"<=2024/12",'配当金履歴一覧'!$B:$B,$B26) -> 2491 | D26: =SUMIFS('配当金履歴一覧'!$F:F,'配当金履歴一覧'!$C:$C,">=2025/1",'配当金履歴一覧'!$C:$C,"<=2025/12",'配当金履歴一覧'!$B:$B,$B26)+SUMIFS('配当金履歴一覧'!$H:H,'配当金履歴一覧'!$C:$C,">=2025/1",'配当金履歴一覧'!$C:$C,"<=2025/12",'配当金履歴一覧'!$B:$B,$B26) -> 3958 | E26: =SUMIFS('配当金履歴一覧'!$F:F,'配当金履歴一覧'!$C:$C,">=2026/1",'配当金履歴一覧'!$C:$C,"<=2026/12",'配当金履歴一覧'!$B:$B,$B26)+SUMIFS('配当金履歴一覧'!$H:H,'配当金履歴一覧'!$C:$C,">=2026/1",'配当金履歴一覧'!$C:$C,"<=2026/12",'配当金履歴一覧'!$B:$B,$B26) -> 0
A27: 2914 | B27: 日本たばこ産業 | C27: =SUMIFS('配当金履歴一覧'!$F:F,'配当金履歴一覧'!$C:$C,">=2024/1",'配当金履歴一覧'!$C:$C,"<=2024/12",'配当金履歴一覧'!$B:$B,$B27)+SUMIFS('配当金履歴一覧'!$H:H,'配当金履歴一覧'!$C:$C,">=2024/1",'配当金履歴一覧'!$C:$C,"<=2024/12",'配当金履歴一覧'!$B:$B,$B27) -> 291 | D27: =SUMIFS('配当金履歴一覧'!$F:F,'配当金履歴一覧'!$C:$C,">=2025/1",'配当金履歴一覧'!$C:$C,"<=2025/12",'配当金履歴一覧'!$B:$B,$B27)+SUMIFS('配当金履歴一覧'!$H:H,'配当金履歴一覧'!$C:$C,">=2025/1",'配当金履歴一覧'!$C:$C,"<=2025/12",'配当金履歴一覧'!$B:$B,$B27) -> 1109 | E27: =SUMIFS('配当金履歴一覧'!$F:F,'配当金履歴一覧'!$C:$C,">=2026/1",'配当金履歴一覧'!$C:$C,"<=2026/12",'配当金履歴一覧'!$B:$B,$B27)+SUMIFS('配当金履歴一覧'!$H:H,'配当金履歴一覧'!$C:$C,">=2026/1",'配当金履歴一覧'!$C:$C,"<=2026/12",'配当金履歴一覧'!$B:$B,$B27) -> 0
A28: 3003 | B28: ヒューリック | C28: =SUMIFS('配当金履歴一覧'!$F:F,'配当金履歴一覧'!$C:$C,">=2024/1",'配当金履歴一覧'!$C:$C,"<=2024/12",'配当金履歴一覧'!$B:$B,$B28)+SUMIFS('配当金履歴一覧'!$H:H,'配当金履歴一覧'!$C:$C,">=2024/1",'配当金履歴一覧'!$C:$C,"<=2024/12",'配当金履歴一覧'!$B:$B,$B28) -> 104 | D28: =SUMIFS('配当金履歴一覧'!$F:F,'配当金履歴一覧'!$C:$C,">=2025/1",'配当金履歴一覧'!$C:$C,"<=2025/12",'配当金履歴一覧'!$B:$B,$B28)+SUMIFS('配当金履歴一覧'!$H:H,'配当金履歴一覧'!$C:$C,">=2025/1",'配当金履歴一覧'!$C:$C,"<=2025/12",'配当金履歴一覧'!$B:$B,$B28) -> 622 | E28: =SUMIFS('配当金履歴一覧'!$F:F,'配当金履歴一覧'!$C:$C,">=2026/1",'配当金履歴一覧'!$C:$C,"<=2026/12",'配当金履歴一覧'!$B:$B,$B28)+SUMIFS('配当金履歴一覧'!$H:H,'配当金履歴一覧'!$C:$C,">=2026/1",'配当金履歴一覧'!$C:$C,"<=2026/12",'配当金履歴一覧'!$B:$B,$B28) -> 0
A29: 4042 | B29: 東ソー | C29: =SUMIFS('配当金履歴一覧'!$F:F,'配当金履歴一覧'!$C:$C,">=2024/1",'配当金履歴一覧'!$C:$C,"<=2024/12",'配当金履歴一覧'!$B:$B,$B29)+SUMIFS('配当金履歴一覧'!$H:H,'配当金履歴一覧'!$C:$C,">=2024/1",'配当金履歴一覧'!$C:$C,"<=2024/12",'配当金履歴一覧'!$B:$B,$B29) -> 0 | D29: =SUMIFS('配当金履歴一覧'!$F:F,'配当金履歴一覧'!$C:$C,">=2025/1",'配当金履歴一覧'!$C:$C,"<=2025/12",'配当金履歴一覧'!$B:$B,$B29)+SUMIFS('配当金履歴一覧'!$H:H,'配当金履歴一覧'!$C:$C,">=2025/1",'配当金履歴一覧'!$C:$C,"<=2025/12",'配当金履歴一覧'!$B:$B,$B29) -> 0 | E29: =SUMIFS('配当金履歴一覧'!$F:F,'配当金履歴一覧'!$C:$C,">=2026/1",'配当金履歴一覧'!$C:$C,"<=2026/12",'配当金履歴一覧'!$B:$B,$B29)+SUMIFS('配当金履歴一覧'!$H:H,'配当金履歴一覧'!$C:$C,">=2026/1",'配当金履歴一覧'!$C:$C,"<=2026/12",'配当金履歴一覧'!$B:$B,$B29) -> 0
A30: 4452 | B30: 花王 | C30: =SUMIFS('配当金履歴一覧'!$F:F,'配当金履歴一覧'!$C:$C,">=2024/1",'配当金履歴一覧'!$C:$C,"<=2024/12",'配当金履歴一覧'!$B:$B,$B30)+SUMIFS('配当金履歴一覧'!$H:H,'配当金履歴一覧'!$C:$C,">=2024/1",'配当金履歴一覧'!$C:$C,"<=2024/12",'配当金履歴一覧'!$B:$B,$B30) -> 152 | D30: =SUMIFS('配当金履歴一覧'!$F:F,'配当金履歴一覧'!$C:$C,">=2025/1",'配当金履歴一覧'!$C:$C,"<=2025/12",'配当金履歴一覧'!$B:$B,$B30)+SUMIFS('配当金履歴一覧'!$H:H,'配当金履歴一覧'!$C:$C,">=2025/1",'配当金履歴一覧'!$C:$C,"<=2025/12",'配当金履歴一覧'!$B:$B,$B30) -> 689 | E30: =SUMIFS('配当金履歴一覧'!$F:F,'配当金履歴一覧'!$C:$C,">=2026/1",'配当金履歴一覧'!$C:$C,"<=2026/12",'配当金履歴一覧'!$B:$B,$B30)+SUMIFS('配当金履歴一覧'!$H:H,'配当金履歴一覧'!$C:$C,">=2026/1",'配当金履歴一覧'!$C:$C,"<=2026/12",'配当金履歴一覧'!$B:$B,$B30) -> 0
... A56: 9513 | B56: 電源開発 | C56: =SUMIFS('配当金履歴一覧'!$F:F,'配当金履歴一覧'!$C:$C,">=2024/1",'配当金履歴一覧'!$C:$C,"<=2024/12",'配当金履歴一覧'!$B:$B,$B56)+SUMIFS('配当金履歴一覧'!$H:H,'配当金履歴一覧'!$C:$C,">=2024/1",'配当金履歴一覧'!$C:$C,"<=2024/12",'配当金履歴一覧'!$B:$B,$B56) -> 1655 | D56: =SUMIFS('配当金履歴一覧'!$F:F,'配当金履歴一覧'!$C:$C,">=2025/1",'配当金履歴一覧'!$C:$C,"<=2025/12",'配当金履歴一覧'!$B:$B,$B56)+SUMIFS('配当金履歴一覧'!$H:H,'配当金履歴一覧'!$C:$C,">=2025/1",'配当金履歴一覧'!$C:$C,"<=2025/12",'配当金履歴一覧'!$B:$B,$B56) -> 2288 | E56: =SUMIFS('配当金履歴一覧'!$F:F,'配当金履歴一覧'!$C:$C,">=2026/1",'配当金履歴一覧'!$C:$C,"<=2026/12",'配当金履歴一覧'!$B:$B,$B56)+SUMIFS('配当金履歴一覧'!$H:H,'配当金履歴一覧'!$C:$C,">=2026/1",'配当金履歴一覧'!$C:$C,"<=2026/12",'配当金履歴一覧'!$B:$B,$B56) -> 0

Sheet 配当金履歴一覧
A1: No. | B1: 銘柄名 | C1: 配当金分配年月 | D1: 配当金単価 （税引き後） | E1: 保有数 （特定） | F1: 受取金額 （特定） | G1: 保有数 （NISA） | H1: 受取金額 （NISA）
A2: =row()-1 -> 1 | B2: バンガード 米国高配当株式ETF | C2: 45352 | D2: 0.59USD | E2: 0 | F2: 0 | G2: 2 | H2: 174
A3: =row()-1 -> 2 | B3: SPDRポートフォリオS&P 500高配当株式ETF | C3: 45352 | D3: 0.33USD | E3: 191 | F3: 7580 | G3: 5 | H3: 249
A4: =row()-1 -> 3 | B4: GMOフィナンシャルホールディングス | C4: 45352 | D4: 7.2 | E4: 20 | F4: 115 | G4: 0 | H4: 0
A5: =row()-1 -> 4 | B5: iシェアーズ コア 米国高配当株 ETF | C5: 45352 | D5: 0.75USD | E5: 51 | F5: 4605 | G5: 3 | H5: 113.3
A6: =row()-1 -> 5 | B6: ジェイエイシーリクルートメント | C6: 45352 | D6: 90 | E6: 16 | F6: 1148 | G6: 0 | H6: 0
A7: =row()-1 -> 6 | B7: キヤノン | C7: 45352 | D7: 70 | E7: 2 | F7: 112 | G7: 0 | H7: 0
A8: =row()-1 -> 7 | B8: キリンホールディングス | C8: 45352 | D8: 36.5 | E8: 9 | F8: 262 | G8: 0 | H8: 0
A9: =row()-1 -> 8 | B9: 住友林業 | C9: 45352 | D9: 65 | E9: 16 | F9: 829 | G9: 0 | H9: 0
A10: =row()-1 -> 9 | B10: 積水ハウス | C10: 45383 | D10: 64 | E10: 15 | F10: 765 | G10: 0 | H10: 0
A11: =row()-1 -> 10 | B11: セブン銀行 | C11: 45444 | D11: 5.5 | E11: 0 | F11: 0 | G11: 50 | H11: 275
A12: =row()-1 -> 11 | B12: 丸紅 | C12: 45444 | D12: 43.5 | E12: 9 | F12: 313 | G12: 3 | H12: 131
A13: =row()-1 -> 12 | B13: オリックス | C13: 45444 | D13: 55.8 | E13: 14 | F13: 624 | G13: 0 | H13: 0
A14: =row()-1 -> 13 | B14: ソフトバンク | C14: 45444 | D14: 43 | E14: 10 | F14: 344 | G14: 0 | H14: 0
A15: =row()-1 -> 14 | B15: 三菱HCキャピタル | C15: 45444 | D15: 10 | E15: 19 | F15: 152 | G15: 0 | H15: 0
A16: =row()-1 -> 15 | B16: SBIホールディングス | C16: 45444 | D16: 130 | E16: 11 | F16: 1140 | G16: 2 | H16: 260
A17: =row()-1 -> 16 | B17: iシェアーズ コア 米国高配当株 ETF | C17: 45444 | D17: 0.83USD | E17: 51 | F17: 5316 | G17: 6 | H17: 785
A18: =row()-1 -> 17 | B18: 双日 | C18: 45444 | D18: 70 | E18: 17 | F18: 949 | G18: 0 | H18: 0
A19: =row()-1 -> 18 | B19: KDDI | C19: 45444 | D19: 70 | E19: 8 | F19: 447 | G19: 2 | H19: 140
A20: =row()-1 -> 19 | B20: 三井物産 | C20: 45444 | D20: 85 | E20: 12 | F20: 813 | G20: 1 | H20: 85
A21: =row()-1 -> 20 | B21: GMOフィナンシャルホールディングス | C21: 45444 | D21: 11.87 | E21: 0 | F21: 0 | G21: 20 | H21: 238
A22: =row()-1 -> 21 | B22: NTT | C22: 45444 | D22: 2.6 | E22: 125 | F22: 260 | G22: 0 | H22: 0
A23: =row()-1 -> 22 | B23: 三菱商事 | C23: 45444 | D23: 35 | E23: 15 | F23: 419 | G23: 0 | H23: 0
A24: =row()-1 -> 23 | B24: 住友商事 | C24: 45444 | D24: 62.5 | E24: 9 | F24: 448 | G24: 2 | H24: 125
A25: =row()-1 -> 24 | B25: 伊藤忠商事 | C25: 45444 | D25: 80 | E25: 6 | F25: 383 | G25: 0 | H25: 0
A26: =row()-1 -> 25 | B26: 東京海上ホールディングス | C26: 45444 | D26: 62.5 | E26: 26 | F26: 1296 | G26: 2 | H26: 125
A27: =row()-1 -> 26 | B27: SOMPOホールディングス | C27: 45444 | D27: 150 | E27: 11 | F27: 1316 | G27: 0 | H27: 0
A28: =row()-1 -> 27 | B28: バンガード 米国高配当株式ETF | C28: 45444 | D28: 0.92USD | E28: 0 | F28: 0 | G28: 8 | H28: 1170
A29: =row()-1 -> 28 | B29: SPDRポートフォリオS&P 500高配当株式ETF | C29: 45444 | D29: 0.43USD | E29: 191 | F29: 10578 | G29: 6 | H29: 417
A30: =row()-1 -> 29 | B30: 電源開発 | C30: 45444 | D30: 55 | E30: 13 | F30: 571 | G30: 3 | H30: 165
A31: =row()-1 -> 30 | B31: ENEOSホールディングス | C31: 45444 | D31: 11 | E31: 0 | F31: 0 | G31: 2 | H31: 22
A32: =row()-1 -> 31 | B32: 武田薬品工業 | C32: 45444 | D32: 94 | E32: 26 | F32: 1948 | G32: 0 | H32: 0
A33: =row()-1 -> 32 | B33: 三井住友フィナンシャルグループ | C33: 45444 | D33: 135 | E33: 10 | F33: 1077 | G33: 0 | H33: 0
A34: =row()-1 -> 33 | B34: 三菱UFJフィナンシャル・グループ | C34: 45444 | D34: 20.5 | E34: 22 | F34: 360 | G34: 0 | H34: 0
A35: =row()-1 -> 34 | B35: 大和ハウス工業 | C35: 45444 | D35: 80 | E35: 8 | F35: 510 | G35: 1 | H35: 80
A36: =row()-1 -> 35 | B36: 長谷工コーポレーション | C36: 45444 | D36: 45 | E36: 8 | F36: 287 | G36: 0 | H36: 0
A37: =row()-1 -> 36 | B37: キヤノン | C37: 45505 | D37: 75 | E37: 2 | F37: 121 | G37: 3 | H37: 225
A38: =row()-1 -> 37 | B38: 花王 | C38: 45536 | D38: 76 | E38: 0 | F38: 0 | G38: 2 | H38: 152
A39: =row()-1 -> 38 | B39: INPEX | C39: 45536 | D39: 43 | E39: 0 | F39: 0 | G39: 4 | H39: 172
A40: =row()-1 -> 39 | B40: ヒューリック | C40: 45536 | D40: 26 | E40: 0 | F40: 0 | G40: 4 | H40: 104
...

Sheet 配当金履歴一覧 のコピー
A1: No. | B1: 銘柄コード | C1: 銘柄名 | D1: 年月 | E1: 単価 | F1: 特定口座（保有株数） | G1: 特定口座（受取金額） | H1: NISA口座（保有株数） | I1: NISA口座（受取金額）
A2: =row()-1 -> 1 | C2: バンガード 米国高配当株式ETF | D2: 45352 | E2: 0.59USD | F2: 0 | G2: 0 | H2: 2 | I2: 174
A3: =row()-1 -> 2 | C3: SPDRポートフォリオS&P 500高配当株式ETF | D3: 45352 | E3: 0.33USD | F3: 191 | G3: 7580 | H3: 5 | I3: 249
A4: =row()-1 -> 3 | C4: GMOフィナンシャルホールディングス | D4: 45352 | E4: 7.2 | F4: 20 | G4: 115 | H4: 0 | I4: 0
A5: =row()-1 -> 4 | C5: iシェアーズ コア 米国高配当株 ETF | D5: 45352 | E5: 0.75USD | F5: 51 | G5: 4605 | H5: 3 | I5: 113.3
A6: =row()-1 -> 5 | C6: ジェイエイシーリクルートメント | D6: 45352 | E6: 90 | F6: 16 | G6: 1148 | H6: 0 | I6: 0
A7: =row()-1 -> 6 | C7: キヤノン | D7: 45352 | E7: 70 | F7: 2 | G7: 112 | H7: 0 | I7: 0
A8: =row()-1 -> 7 | C8: キリンホールディングス | D8: 45352 | E8: 36.5 | F8: 9 | G8: 262 | H8: 0 | I8: 0
A9: =row()-1 -> 8 | C9: 住友林業 | D9: 45352 | E9: 65 | F9: 16 | G9: 829 | H9: 0 | I9: 0
A10: =row()-1 -> 9 | C10: 積水ハウス | D10: 45383 | E10: 64 | F10: 15 | G10: 765 | H10: 0 | I10: 0
A11: =row()-1 -> 10 | C11: セブン銀行 | D11: 45444 | E11: 5.5 | F11: 0 | G11: 0 | H11: 50 | I11: 275
A12: =row()-1 -> 11 | C12: 丸紅 | D12: 45444 | E12: 43.5 | F12: 9 | G12: 313 | H12: 3 | I12: 131
A13: =row()-1 -> 12 | C13: オリックス | D13: 45444 | E13: 55.8 | F13: 14 | G13: 624 | H13: 0 | I13: 0
A14: =row()-1 -> 13 | C14: ソフトバンク | D14: 45444 | E14: 43 | F14: 10 | G14: 344 | H14: 0 | I14: 0
A15: =row()-1 -> 14 | C15: 三菱HCキャピタル | D15: 45444 | E15: 10 | F15: 19 | G15: 152 | H15: 0 | I15: 0
A16: =row()-1 -> 15 | C16: SBIホールディングス | D16: 45444 | E16: 130 | F16: 11 | G16: 1140 | H16: 2 | I16: 260
A17: =row()-1 -> 16 | C17: iシェアーズ コア 米国高配当株 ETF | D17: 45444 | E17: 0.83USD | F17: 51 | G17: 5316 | H17: 6 | I17: 785
A18: =row()-1 -> 17 | C18: 双日 | D18: 45444 | E18: 70 | F18: 17 | G18: 949 | H18: 0 | I18: 0
A19: =row()-1 -> 18 | C19: KDDI | D19: 45444 | E19: 70 | F19: 8 | G19: 447 | H19: 2 | I19: 140
A20: =row()-1 -> 19 | C20: 三井物産 | D20: 45444 | E20: 85 | F20: 12 | G20: 813 | H20: 1 | I20: 85
A21: =row()-1 -> 20 | C21: GMOフィナンシャルホールディングス | D21: 45444 | E21: 11.87 | F21: 0 | G21: 0 | H21: 20 | I21: 238
A22: =row()-1 -> 21 | C22: NTT | D22: 45444 | E22: 2.6 | F22: 125 | G22: 260 | H22: 0 | I22: 0
A23: =row()-1 -> 22 | C23: 三菱商事 | D23: 45444 | E23: 35 | F23: 15 | G23: 419 | H23: 0 | I23: 0
A24: =row()-1 -> 23 | C24: 住友商事 | D24: 45444 | E24: 62.5 | F24: 9 | G24: 448 | H24: 2 | I24: 125
A25: =row()-1 -> 24 | C25: 伊藤忠商事 | D25: 45444 | E25: 80 | F25: 6 | G25: 383 | H25: 0 | I25: 0
A26: =row()-1 -> 25 | C26: 東京海上ホールディングス | D26: 45444 | E26: 62.5 | F26: 26 | G26: 1296 | H26: 2 | I26: 125
A27: =row()-1 -> 26 | C27: SOMPOホールディングス | D27: 45444 | E27: 150 | F27: 11 | G27: 1316 | H27: 0 | I27: 0
A28: =row()-1 -> 27 | C28: バンガード 米国高配当株式ETF | D28: 45444 | E28: 0.92USD | F28: 0 | G28: 0 | H28: 8 | I28: 1170
A29: =row()-1 -> 28 | C29: SPDRポートフォリオS&P 500高配当株式ETF | D29: 45444 | E29: 0.43USD | F29: 191 | G29: 10578 | H29: 6 | I29: 417
A30: =row()-1 -> 29 | C30: 電源開発 | D30: 45444 | E30: 55 | F30: 13 | G30: 571 | H30: 3 | I30: 165
A31: =row()-1 -> 30 | C31: ENEOSホールディングス | D31: 45444 | E31: 11 | F31: 0 | G31: 0 | H31: 2 | I31: 22
A32: =row()-1 -> 31 | C32: 武田薬品工業 | D32: 45444 | E32: 94 | F32: 26 | G32: 1948 | H32: 0 | I32: 0
A33: =row()-1 -> 32 | C33: 三井住友フィナンシャルグループ | D33: 45444 | E33: 135 | F33: 10 | G33: 1077 | H33: 0 | I33: 0
A34: =row()-1 -> 33 | C34: 三菱UFJフィナンシャル・グループ | D34: 45444 | E34: 20.5 | F34: 22 | G34: 360 | H34: 0 | I34: 0
A35: =row()-1 -> 34 | C35: 大和ハウス工業 | D35: 45444 | E35: 80 | F35: 8 | G35: 510 | H35: 1 | I35: 80
A36: =row()-1 -> 35 | C36: 長谷工コーポレーション | D36: 45444 | E36: 45 | F36: 8 | G36: 287 | H36: 0 | I36: 0
A37: =row()-1 -> 36 | C37: キヤノン | D37: 45505 | E37: 75 | F37: 2 | G37: 121 | H37: 3 | I37: 225
A38: =row()-1 -> 37 | C38: 花王 | D38: 45536 | E38: 76 | F38: 0 | G38: 0 | H38: 2 | I38: 152
A39: =row()-1 -> 38 | C39: INPEX | D39: 45536 | E39: 43 | F39: 0 | G39: 0 | H39: 4 | I39: 172
A40: =row()-1 -> 39 | C40: ヒューリック | D40: 45536 | E40: 26 | F40: 0 | G40: 0 | H40: 4 | I40: 104
...

Sheet 新NISA戦略
A1: 年 | B1: 月 | C1: 予定投資額 （積立投資枠） | D1: 予定投資額 （成長投資枠） | E1: 予定投資額合計 | F1: 新NISA投資枠残額 | G1: 内訳 | I1: 月額 | J1: 年額
A2: 2024 | B2: 1 | C2: =I2 -> 53000 | D2: =I3 -> 80000 | E2: =C2+D2 -> 133000 | F2: =18000000-E2 -> 17867000 | G2: 新NISA | H2: 積立投資枠 | I2: 53000 | J2: =I2*12 -> 636000
B3: 2 | C3: =$I$2+C2 -> 106000 | D3: =$I$3+D2 -> 160000 | E3: =C3+D3 -> 266000 | F3: =18000000-E3 -> 17734000 | H3: 成長投資枠 | I3: 80000 | J3: =I3*12 -> 960000
B4: 3 | C4: =$I$2+C3 -> 159000 | D4: =$I$3+D3 -> 240000 | E4: =C4+D4 -> 399000 | F4: =18000000-E4 -> 17601000 | G4: 合計 | I4: =SUM(I2:I3) -> 133000 | J4: =I4*12 -> 1596000
B5: 4 | C5: =$I$2+C4 -> 212000 | D5: =$I$3+D4 -> 320000 | E5: =C5+D5 -> 532000 | F5: =18000000-E5 -> 17468000
B6: 5 | C6: =$I$2+C5 -> 265000 | D6: =$I$3+D5 -> 400000 | E6: =C6+D6 -> 665000 | F6: =18000000-E6 -> 17335000
B7: 6 | C7: =$I$2+C6 -> 318000 | D7: =$I$3+D6 -> 480000 | E7: =C7+D7 -> 798000 | F7: =18000000-E7 -> 17202000
B8: 7 | C8: =$I$2+C7 -> 371000 | D8: =$I$3+D7 -> 560000 | E8: =C8+D8 -> 931000 | F8: =18000000-E8 -> 17069000
B9: 8 | C9: =$I$2+C8 -> 424000 | D9: =$I$3+D8 -> 640000 | E9: =C9+D9 -> 1064000 | F9: =18000000-E9 -> 16936000
B10: 9 | C10: =$I$2+C9 -> 477000 | D10: =$I$3+D9 -> 720000 | E10: =C10+D10 -> 1197000 | F10: =18000000-E10 -> 16803000
B11: 10 | C11: =$I$2+C10 -> 530000 | D11: =$I$3+D10 -> 800000 | E11: =C11+D11 -> 1330000 | F11: =18000000-E11 -> 16670000
B12: 11 | C12: =$I$2+C11 -> 583000 | D12: =$I$3+D11 -> 880000 | E12: =C12+D12 -> 1463000 | F12: =18000000-E12 -> 16537000
B13: 12 | C13: =$I$2+C12 -> 636000 | D13: =$I$3+D12 -> 960000 | E13: =C13+D13 -> 1596000 | F13: =18000000-E13 -> 16404000
A14: 2025 | B14: 1 | C14: =$I$2+C13 -> 689000 | D14: =$I$3+D13 -> 1040000 | E14: =C14+D14 -> 1729000 | F14: =18000000-E14 -> 16271000
B15: 2 | C15: =$I$2+C14 -> 742000 | D15: =$I$3+D14 -> 1120000 | E15: =C15+D15 -> 1862000 | F15: =18000000-E15 -> 16138000
B16: 3 | C16: =$I$2+C15 -> 795000 | D16: =$I$3+D15 -> 1200000 | E16: =C16+D16 -> 1995000 | F16: =18000000-E16 -> 16005000
B17: 4 | C17: =$I$2+C16 -> 848000 | D17: =$I$3+D16 -> 1280000 | E17: =C17+D17 -> 2128000 | F17: =18000000-E17 -> 15872000
B18: 5 | C18: =$I$2+C17 -> 901000 | D18: =$I$3+D17 -> 1360000 | E18: =C18+D18 -> 2261000 | F18: =18000000-E18 -> 15739000
B19: 6 | C19: =$I$2+C18 -> 954000 | D19: =$I$3+D18 -> 1440000 | E19: =C19+D19 -> 2394000 | F19: =18000000-E19 -> 15606000
B20: 7 | C20: =$I$2+C19 -> 1007000 | D20: =$I$3+D19 -> 1520000 | E20: =C20+D20 -> 2527000 | F20: =18000000-E20 -> 15473000
B21: 8 | C21: =$I$2+C20 -> 1060000 | D21: =$I$3+D20 -> 1600000 | E21: =C21+D21 -> 2660000 | F21: =18000000-E21 -> 15340000
B22: 9 | C22: =$I$2+C21 -> 1113000 | D22: =$I$3+D21 -> 1680000 | E22: =C22+D22 -> 2793000 | F22: =18000000-E22 -> 15207000
B23: 10 | C23: =$I$2+C22 -> 1166000 | D23: =$I$3+D22 -> 1760000 | E23: =C23+D23 -> 2926000 | F23: =18000000-E23 -> 15074000
B24: 11 | C24: =$I$2+C23 -> 1219000 | D24: =$I$3+D23 -> 1840000 | E24: =C24+D24 -> 3059000 | F24: =18000000-E24 -> 14941000
B25: 12 | C25: =$I$2+C24 -> 1272000 | D25: =$I$3+D24 -> 1920000 | E25: =C25+D25 -> 3192000 | F25: =18000000-E25 -> 14808000
A26: 2026 | B26: 1 | C26: =$I$2+C25 -> 1325000 | D26: =$I$3+D25 -> 2000000 | E26: =C26+D26 -> 3325000 | F26: =18000000-E26 -> 14675000
B27: 2 | C27: =$I$2+C26 -> 1378000 | D27: =$I$3+D26 -> 2080000 | E27: =C27+D27 -> 3458000 | F27: =18000000-E27 -> 14542000
B28: 3 | C28: =$I$2+C27 -> 1431000 | D28: =$I$3+D27 -> 2160000 | E28: =C28+D28 -> 3591000 | F28: =18000000-E28 -> 14409000
B29: 4 | C29: =$I$2+C28 -> 1484000 | D29: =$I$3+D28 -> 2240000 | E29: =C29+D29 -> 3724000 | F29: =18000000-E29 -> 14276000
B30: 5 | C30: =$I$2+C29 -> 1537000 | D30: =$I$3+D29 -> 2320000 | E30: =C30+D30 -> 3857000 | F30: =18000000-E30 -> 14143000
B31: 6 | C31: =$I$2+C30 -> 1590000 | D31: =$I$3+D30 -> 2400000 | E31: =C31+D31 -> 3990000 | F31: =18000000-E31 -> 14010000
B32: 7 | C32: =$I$2+C31 -> 1643000 | D32: =$I$3+D31 -> 2480000 | E32: =C32+D32 -> 4123000 | F32: =18000000-E32 -> 13877000
B33: 8 | C33: =$I$2+C32 -> 1696000 | D33: =$I$3+D32 -> 2560000 | E33: =C33+D33 -> 4256000 | F33: =18000000-E33 -> 13744000
B34: 9 | C34: =$I$2+C33 -> 1749000 | D34: =$I$3+D33 -> 2640000 | E34: =C34+D34 -> 4389000 | F34: =18000000-E34 -> 13611000
B35: 10 | C35: =$I$2+C34 -> 1802000 | D35: =$I$3+D34 -> 2720000 | E35: =C35+D35 -> 4522000 | F35: =18000000-E35 -> 13478000
B36: 11 | C36: =$I$2+C35 -> 1855000 | D36: =$I$3+D35 -> 2800000 | E36: =C36+D36 -> 4655000 | F36: =18000000-E36 -> 13345000
B37: 12 | C37: =$I$2+C36 -> 1908000 | D37: =$I$3+D36 -> 2880000 | E37: =C37+D37 -> 4788000 | F37: =18000000-E37 -> 13212000
A38: 2027 | B38: 1 | C38: =$I$2+C37 -> 1961000 | D38: =$I$3+D37 -> 2960000 | E38: =C38+D38 -> 4921000 | F38: =18000000-E38 -> 13079000
B39: 2 | C39: =$I$2+C38 -> 2014000 | D39: =$I$3+D38 -> 3040000 | E39: =C39+D39 -> 5054000 | F39: =18000000-E39 -> 12946000
B40: 3 | C40: =$I$2+C39 -> 2067000 | D40: =$I$3+D39 -> 3120000 | E40: =C40+D40 -> 5187000 | F40: =18000000-E40 -> 12813000
...
